Workbook

Sheet Resumen
A2: Inventario IXTLAHUACA - Resumen
A3: Total Dispositivos y/o Direcciones IPs Descubiertos | F3: 31064
B4: Dispositivos Identificados | F4: =F5+F10+F13+F14
C5: Total Servidores | F5: 10563
D6: Servidores con Cortex | F6: 6249
D7: Servidores sin Cortex | F7: 4314
E8: Cortex Soportado | F8: =F7-F9
E9: Cortex no Soportado | F9: {=SUM(COUNTIFS(Inventario!E6:E1048576, {"Oracle Solaris","Windows Server 2008 R2","Windows Server 2003 R2","SunOS 10","SunOS 11.1","SunOS 11.2","SunOS 11.3","IBM AIX 6.1","IBM AIX 7.1","IBM AIX 7.2","IBM AIX 5.3","SunOS 9","SunOS 11.4.23.69.3","SunOS 11.0","SunOS 11.4","SunOS 11.4.0.15.0"}, Inventario!F6:F1048576, "NO"))}
C10: PCs | F10: 255
D11: PCs con Cortex | F11: 200
D12: PCs sin Cortex | F12: 55
C13: Dispositivos de Red o colaboración | F13: 1025
C14: Otros dispositivos identificados (No servidores) | F14: =COUNTA('Inventario Identificados'!A5:A1048576)
B15: IPs No Identificados (Servidores) | F15: =COUNTA('Inventario No Identificados'!A5:A1048576)
B16: IPs No Identificados (No Vendor) | F16: =F3-F4-F15
A19: Servidores IXTLAHUACA - Vulnerabilidades
A20: Servidores con vulnerabilidades Críticas | E20: =COUNTIF('Inventario'!H6:H1048576,">0")
A21: Servidores con vulnerabilidades Altas | E21: =COUNTIF('Inventario'!I6:I1048576,">0")
A22: Servidores con EoL | E22: 5352

Sheet Inventario - PC
A3: PCs IXTLAHUACA - Inventario
A4: No | B4: Hostname | C4: Dir IP | D4: MAC | E4: Sistema Operativo | F4: Cortex | G4: Virtual Patching
A6: 1 | B6: ADINFRHVIADMXCO | C6: 10.191.143.167 200.68.130.150 | D6: 00:50:56:99:13:A8 | E6: Windows 7 | F6: SI | G6: NO
A7: 2 | B7: CLVCWK7CJUPA001 | C7: 10.191.143.77 200.68.130.130 | D7: 00:50:56:9E:78:E2 | E7: Windows 7 | F7: SI | G7: NO
A8: 3 | B8: VWK7BUSEMD01 | C8: 10.191.148.203 200.68.130.151 | D8: 00:50:56:9E:29:26 | E8: Windows 7 | F8: SI | G8: NO
A9: 4 | B9: SVDAS0208ADMXCO.TELCEL.NET | C9: 10.119.160.69 | D9: 00:50:56:9E:2C:43 | E9: Windows 10 | F9: SI | G9: NO
A10: 5 | B10: VWK7BUSEMD03 | C10: 10.191.148.205 200.68.130.150 | D10: 00:50:56:9E:5E:52 | E10: Windows 7 | F10: SI | G10: NO
A11: 6 | B11: VWK7BUSEMD02 | C11: 10.191.148.204 200.68.130.151 | D11: 00:50:56:9E:2A:14 | E11: Windows 7 | F11: SI | G11: NO
A12: 7 | B12: ITHHPOIDVPAD007.TELCEL.NET | C12: 10.191.62.133 200.68.130.150 | D12: 00:50:56:86:D8:33 | E12: Windows 7 | F12: SI | G12: NO
A13: 8 | B13: V-W10PPRO-D01 | C13: 10.191.33.225 200.68.130.150 | D13: 00:50:56:9E:09:5E | E13: Windows 10 | F13: SI | G13: NO
A14: 9 | B14: ITHHWCTX2MI02 | C14: 10.119.99.78 200.68.130.132 | D14: 00:50:56:BD:05:B2 | E14: Windows 11 | F14: SI | G14: NO
A15: 10 | B15: ITHHWCTX2MI10 | C15: 10.119.99.51 200.68.130.151 | D15: 00:50:56:BD:33:DA | E15: Windows 11 | F15: SI | G15: NO
A16: 11 | B16: ITHHWCTX2MI03 | C16: 10.119.99.79 200.68.130.131 | D16: 00:50:56:BD:EF:CD | E16: Windows 11 | F16: SI | G16: NO
A17: 12 | B17: ITHHWCTX2VDIA02 | C17: 10.119.99.75 200.68.130.151 | D17: 00:50:56:BD:91:59 | E17: Windows 11 | F17: SI | G17: NO
... A260: 255 | B260: ITHVHWVDISW140 | C260: 10.59.208.162 200.68.130.132 | D260: 28:6E:D4:89:7F:76 | E260: Windows 10 | F260: SI | G260: NO

Sheet Inventario - Red
A3: Network Devices IXTLAHUACA - Inventario
A4: Adapter | B4: Hostname | C4: IPs | D4: MAC | E4: Manufacturer
A5: cisco_apic_adapter csv_adapter | B5: 9CTIXT31021701 | C5: 10.255.19.231 172.17.6.10 172.19.128.2 fc00::1
A6: cisco_apic_adapter csv_adapter | B6: 9CTIXT32021401 | C6: 10.255.19.229 172.17.6.11 172.19.128.1 fc00::1
A7: cisco_apic_adapter csv_adapter | B7: 9CTIXT32011901 | C7: 10.255.19.228 172.17.6.12 172.19.128.4 fc00::1
A8: cisco_apic_adapter csv_adapter | B8: 9LF_IXT2_20517_06 | C8: 172.17.6.126 172.18.220.69
A9: cisco_apic_adapter csv_adapter | B9: 9CTIXT12011401 | C9: 10.255.19.232 172.17.6.13 172.19.128.5 fc00::1
A10: cisco_apic_adapter csv_adapter | B10: 9LF_IXT1_10718_03 | C10: 172.17.7.31 172.19.216.83
A11: cisco_apic_adapter csv_adapter | B11: 9CTIXT21021801 | C11: 10.255.19.230 172.17.6.14 172.19.128.3 fc00::1
A12: cisco_apic_adapter csv_adapter | B12: 9LF_IXT2_20517_05 | C12: 172.17.6.128 172.18.200.66
A13: cisco_apic_adapter csv_adapter | B13: 9LF_IXT1_10718_02 | C13: 172.17.7.30 172.19.216.84
A14: cisco_apic_adapter csv_adapter | B14: 9LF_IXT1_10918_04 | C14: 172.17.7.29 172.19.216.82
A15: cisco_apic_adapter csv_adapter | B15: 9LF_IXT1_11418_02 | C15: 172.17.7.23 172.19.176.73
A16: cisco_apic_adapter csv_adapter | B16: 9LF_IXT1_10918_03 | C16: 172.17.7.28 172.19.216.81
... A286: cisco_apic_adapter csv_adapter | B286: 9LF_IXT3_21219_01 | C286: 10.59.214.76 10.59.215.76 172.17.128.64
A287: cisco_apic_adapter | C287: 172.17.2.26 | D287: B0:26:80:69:FB:B2 | E287: (Cisco Systems, Inc)
A288: cisco_apic_adapter | C288: 55.55.5.34 | D288: B0:26:80:69:FA:F2 | E288: (Cisco Systems, Inc)
A289: cisco_apic_adapter | C289: 10.59.129.146 | D289: 88:94:71:BC:3D:30 | E289: (Brocade Communications Systems LLC)
A290: cisco_apic_adapter | C290: 10.59.89.15 | D290: 88:94:71:99:6F:25 | E290: (Brocade Communications Systems LLC)
A291: cisco_apic_adapter | C291: 172.17.7.195 | D291: 0C:D0:F8:35:F3:41 | E291: (Cisco Systems, Inc)
A292: cisco_apic_adapter | C292: 10.119.157.22 | D292: 00:35:1A:D9:FE:70 | E292: (Cisco Systems, Inc)
A293: cisco_apic_adapter | C293: 10.119.157.21 | D293: 00:35:1A:E5:B6:F0 | E293: (Cisco Systems, Inc)
A294: cisco_apic_adapter | C294: 10.119.157.19 | D294: 8C:60:4F:B3:9E:C1 | E294: (Cisco Systems, Inc)
A295: cisco_apic_adapter | C295: 10.119.157.34 | D295: 58:AC:78:E0:60:BC | E295: (Cisco Systems, Inc)
A296: cisco_apic_adapter | C296: 172.17.7.243 | D296: 50:61:BF:E9:2B:41 | E296: (Cisco Systems, Inc)
A297: cisco_apic_adapter | C297: 10.119.109.99 | D297: 88:94:71:26:76:28 | E297: (Brocade Communications Systems LLC)
A298: cisco_apic_adapter cisco_apic_adapter cisco_apic_adapter cisco_apic_adapter cisco_apic_adapter cisco_apic_adapter cisco_apic_adapter cisco_apic_adapter | C298: 10.119.185.133 | D298: 00:04:96:26:6B:D7 | E298: (Extreme Networks Headquarters)
... A306: cisco_apic_adapter | C306: 172.17.7.160 | D306: 54:86:BC:75:71:C1 | E306: (Cisco Systems, Inc)
A307: cisco_apic_adapter | D307: 3C:08:F6:8B:C9:3F | E307: (Cisco Systems, Inc)
A308: cisco_apic_adapter | C308: 10.59.11.82 | D308: 00:05:33:D3:ED:0E | E308: (Brocade Communications Systems LLC)
A309: cisco_apic_adapter | C309: 172.17.7.197 | D309: 0C:D0:F8:72:0A:C1 | E309: (Cisco Systems, Inc)
A310: cisco_apic_adapter | C310: 172.17.7.165 | D310: 50:61:BF:E9:29:C1 | E310: (Cisco Systems, Inc)
A311: cisco_apic_adapter | C311: 172.17.7.154 | D311: C4:C6:03:D2:70:41 | E311: (Cisco Systems, Inc)
A312: cisco_apic_adapter | C312: 10.59.129.81 | D312: 88:94:71:66:BD:0F | E312: (Brocade Communications Systems LLC)
A313: cisco_apic_adapter | C313: 10.119.109.101 | D313: 88:94:71:25:7E:37 | E313: (Brocade Communications Systems LLC)
A314: cisco_apic_adapter | C314: 172.17.7.161 | D314: C4:C6:03:D2:7A:41 | E314: (Cisco Systems, Inc)
A315: cisco_apic_adapter | C315: 172.17.7.196 | D315: 0C:D0:F8:B8:9F:C1 | E315: (Cisco Systems, Inc)
A316: cisco_apic_adapter | C316: 10.119.109.177 | D316: 88:94:71:63:5C:9D | E316: (Brocade Communications Systems LLC)
A317: cisco_apic_adapter | C317: 10.119.109.105 | D317: 88:94:71:25:EE:F9 | E317: (Brocade Communications Systems LLC)
A318: cisco_apic_adapter | C318: 172.17.7.194 | D318: 0C:D0:F8:35:F6:41 | E318: (Cisco Systems, Inc)
...

Sheet Inventario
A3: Servidores IXTLAHUACA - Inventario
A4: No | B4: Hostname | C4: Dir IP | D4: MAC | E4: Sistema Operativo | F4: Cortex | G4: Virtual Patching (Trend Micro) | H4: Vulnerabilidades | J4: Comentarios
H5: #Criticas | I5: #Altas
A6: 1 | B6: ITHVHWIPAWPAP01 | C6: 10.59.195.190 200.68.130.132 | D6: 00:50:56:81:0E:86 | E6: Windows Server 2022 | F6: SI | G6: SI | H6: 4 | I6: 70 | J6: =IF(F6="SI", "NA", IF(OR(E6="Oracle Solaris", E6="Windows Server 2008 R2", E6="Windows Server 2003 R2", E6="SunOS 10", E6="SunOS 11.1", E6="SunOS 11.2", E6="SunOS 11.3", E6="IBM AIX 6.1", E6="IBM AIX 7.1", E6="IBM AIX 7.2", E6="IBM AIX 5.3", E6="SunOS 9", E6="SunOS 11.4.23.69.3", E6="SunOS 11.0", E6="SunOS 11.4", E6="SunOS 11.4.0.15.0"), "Cortex not supported", "NA"))
A7: 2 | B7: ITHHWHUEPRO18 | C7: 10.119.249.107 200.68.130.151 | D7: FA:16:3E:12:A4:00 | E7: Linux Red Hat 7.9 | F7: SI | G7: SI | H7: 971 | I7: 3701 | J7: =IF(F7="SI", "NA", IF(OR(E7="Oracle Solaris", E7="Windows Server 2008 R2", E7="Windows Server 2003 R2", E7="SunOS 10", E7="SunOS 11.1", E7="SunOS 11.2", E7="SunOS 11.3", E7="IBM AIX 6.1", E7="IBM AIX 7.1", E7="IBM AIX 7.2", E7="IBM AIX 5.3", E7="SunOS 9", E7="SunOS 11.4.23.69.3", E7="SunOS 11.0", E7="SunOS 11.4", E7="SunOS 11.4.0.15.0"), "Cortex not supported", "NA"))
A8: 3 | B8: ITHVVWRPADRBD02 | C8: 10.59.240.64 200.68.130.150 | D8: 00:50:56:81:1B:EE | E8: Linux Red Hat 8.10 | F8: SI | G8: SI | H8: 162 | I8: 943 | J8: =IF(F8="SI", "NA", IF(OR(E8="Oracle Solaris", E8="Windows Server 2008 R2", E8="Windows Server 2003 R2", E8="SunOS 10", E8="SunOS 11.1", E8="SunOS 11.2", E8="SunOS 11.3", E8="IBM AIX 6.1", E8="IBM AIX 7.1", E8="IBM AIX 7.2", E8="IBM AIX 5.3", E8="SunOS 9", E8="SunOS 11.4.23.69.3", E8="SunOS 11.0", E8="SunOS 11.4", E8="SunOS 11.4.0.15.0"), "Cortex not supported", "NA"))
A9: 4 | B9: IXVPECIAPS001 | C9: 10.191.33.94 200.68.130.150 | D9: 00:50:56:86:A8:23 | E9: Linux Red Hat 7.9 | F9: SI | G9: SI | H9: 102 | I9: 406 | J9: =IF(F9="SI", "NA", IF(OR(E9="Oracle Solaris", E9="Windows Server 2008 R2", E9="Windows Server 2003 R2", E9="SunOS 10", E9="SunOS 11.1", E9="SunOS 11.2", E9="SunOS 11.3", E9="IBM AIX 6.1", E9="IBM AIX 7.1", E9="IBM AIX 7.2", E9="IBM AIX 5.3", E9="SunOS 9", E9="SunOS 11.4.23.69.3", E9="SunOS 11.0", E9="SunOS 11.4", E9="SunOS 11.4.0.15.0"), "Cortex not supported", "NA"))
A10: 5 | B10: IXVPECIAPS002 | C10: 10.191.33.95 200.68.130.150 | D10: 00:50:56:86:B1:FC | E10: Linux Red Hat 7.9 | F10: SI | G10: SI | H10: 106 | I10: 450 | J10: =IF(F10="SI", "NA", IF(OR(E10="Oracle Solaris", E10="Windows Server 2008 R2", E10="Windows Server 2003 R2", E10="SunOS 10", E10="SunOS 11.1", E10="SunOS 11.2", E10="SunOS 11.3", E10="IBM AIX 6.1", E10="IBM AIX 7.1", E10="IBM AIX 7.2", E10="IBM AIX 5.3", E10="SunOS 9", E10="SunOS 11.4.23.69.3", E10="SunOS 11.0", E10="SunOS 11.4", E10="SunOS 11.4.0.15.0"), "Cortex not supported", "NA"))
A11: 6 | B11: IXVPECIAPS003 | C11: 10.191.33.96 200.68.130.151 | D11: 00:50:56:86:A3:4E | E11: Linux Red Hat 7.9 | F11: SI | G11: SI | H11: 100 | I11: 404 | J11: =IF(F11="SI", "NA", IF(OR(E11="Oracle Solaris", E11="Windows Server 2008 R2", E11="Windows Server 2003 R2", E11="SunOS 10", E11="SunOS 11.1", E11="SunOS 11.2", E11="SunOS 11.3", E11="IBM AIX 6.1", E11="IBM AIX 7.1", E11="IBM AIX 7.2", E11="IBM AIX 5.3", E11="SunOS 9", E11="SunOS 11.4.23.69.3", E11="SunOS 11.0", E11="SunOS 11.4", E11="SunOS 11.4.0.15.0"), "Cortex not supported", "NA"))
A12: 7 | B12: IXVPECIAPS004 | C12: 10.191.33.97 200.68.130.131 | D12: 00:50:56:86:8C:89 | E12: Linux Red Hat 7.9 | F12: SI | G12: SI | H12: 100 | I12: 421 | J12: =IF(F12="SI", "NA", IF(OR(E12="Oracle Solaris", E12="Windows Server 2008 R2", E12="Windows Server 2003 R2", E12="SunOS 10", E12="SunOS 11.1", E12="SunOS 11.2", E12="SunOS 11.3", E12="IBM AIX 6.1", E12="IBM AIX 7.1", E12="IBM AIX 7.2", E12="IBM AIX 5.3", E12="SunOS 9", E12="SunOS 11.4.23.69.3", E12="SunOS 11.0", E12="SunOS 11.4", E12="SunOS 11.4.0.15.0"), "Cortex not supported", "NA"))
A13: 8 | B13: ITHVHWPSPWPAP02 | C13: 10.152.30.33 200.68.130.132 | D13: 00:50:56:81:E0:4E | E13: Windows Server 2022 | F13: SI | G13: SI | H13: 0 | I13: 0 | J13: =IF(F13="SI", "NA", IF(OR(E13="Oracle Solaris", E13="Windows Server 2008 R2", E13="Windows Server 2003 R2", E13="SunOS 10", E13="SunOS 11.1", E13="SunOS 11.2", E13="SunOS 11.3", E13="IBM AIX 6.1", E13="IBM AIX 7.1", E13="IBM AIX 7.2", E13="IBM AIX 5.3", E13="SunOS 9", E13="SunOS 11.4.23.69.3", E13="SunOS 11.0", E13="SunOS 11.4", E13="SunOS 11.4.0.15.0"), "Cortex not supported", "NA"))
A14: 9 | B14: ITHVHWPSPWPAP01 | C14: 10.152.30.32 200.68.130.132 | D14: 00:50:56:81:F1:05 | E14: Windows Server 2022 | F14: SI | G14: SI | H14: 1 | I14: 102 | J14: =IF(F14="SI", "NA", IF(OR(E14="Oracle Solaris", E14="Windows Server 2008 R2", E14="Windows Server 2003 R2", E14="SunOS 10", E14="SunOS 11.1", E14="SunOS 11.2", E14="SunOS 11.3", E14="IBM AIX 6.1", E14="IBM AIX 7.1", E14="IBM AIX 7.2", E14="IBM AIX 5.3", E14="SunOS 9", E14="SunOS 11.4.23.69.3", E14="SunOS 11.0", E14="SunOS 11.4", E14="SunOS 11.4.0.15.0"), "Cortex not supported", "NA"))
A15: 10 | B15: ITHVHWPSPWPAP03 | C15: 10.152.30.34 200.68.130.132 | D15: 00:50:56:81:3E:2A | E15: Windows Server 2022 | F15: SI | G15: SI | H15: 0 | I15: 0 | J15: =IF(F15="SI", "NA", IF(OR(E15="Oracle Solaris", E15="Windows Server 2008 R2", E15="Windows Server 2003 R2", E15="SunOS 10", E15="SunOS 11.1", E15="SunOS 11.2", E15="SunOS 11.3", E15="IBM AIX 6.1", E15="IBM AIX 7.1", E15="IBM AIX 7.2", E15="IBM AIX 5.3", E15="SunOS 9", E15="SunOS 11.4.23.69.3", E15="SunOS 11.0", E15="SunOS 11.4", E15="SunOS 11.4.0.15.0"), "Cortex not supported", "NA"))
A16: 11 | B16: ITHVHWMPPWPAP02 | C16: 10.152.75.68 200.68.130.132 | D16: 00:50:56:81:B7:64 | E16: Windows Server 2022 | F16: SI | G16: SI | H16: 1 | I16: 239 | J16: =IF(F16="SI", "NA", IF(OR(E16="Oracle Solaris", E16="Windows Server 2008 R2", E16="Windows Server 2003 R2", E16="SunOS 10", E16="SunOS 11.1", E16="SunOS 11.2", E16="SunOS 11.3", E16="IBM AIX 6.1", E16="IBM AIX 7.1", E16="IBM AIX 7.2", E16="IBM AIX 5.3", E16="SunOS 9", E16="SunOS 11.4.23.69.3", E16="SunOS 11.0", E16="SunOS 11.4", E16="SunOS 11.4.0.15.0"), "Cortex not supported", "NA"))
A17: 12 | B17: ITHVVMSVDAWAP01 | C17: 10.152.75.58 200.68.130.131 | D17: 00:50:56:81:5A:B4 | E17: Windows Server 2022 | F17: SI | G17: SI | H17: 21 | I17: 124 | J17: =IF(F17="SI", "NA", IF(OR(E17="Oracle Solaris", E17="Windows Server 2008 R2", E17="Windows Server 2003 R2", E17="SunOS 10", E17="SunOS 11.1", E17="SunOS 11.2", E17="SunOS 11.3", E17="IBM AIX 6.1", E17="IBM AIX 7.1", E17="IBM AIX 7.2", E17="IBM AIX 5.3", E17="SunOS 9", E17="SunOS 11.4.23.69.3", E17="SunOS 11.0", E17="SunOS 11.4", E17="SunOS 11.4.0.15.0"), "Cortex not supported", "NA"))
... A4775: 4770 | B4775: ITHVRHTREPRAP01 | C4775: 10.152.30.78 200.68.130.130 | D4775: 56:6F:3C:FD:02:4F | E4775: Linux Red Hat 8.10 | F4775: SI | G4775: NO | H4775: 55 | I4775: 0 | J4775: =IF(F4775="SI", "NA", IF(OR(E4775="Oracle Solaris", E4775="Windows Server 2008 R2", E4775="Windows Server 2003 R2", E4775="SunOS 10", E4775="SunOS 11.1", E4775="SunOS 11.2", E4775="SunOS 11.3", E4775="IBM AIX 6.1", E4775="IBM AIX 7.1", E4775="IBM AIX 7.2", E4775="IBM AIX 5.3", E4775="SunOS 9", E4775="SunOS 11.4.23.69.3", E4775="SunOS 11.0", E4775="SunOS 11.4", E4775="SunOS 11.4.0.15.0"), "Cortex not supported", "NA"))
A4776: 4771 | B4776: IXTAI3 | C4776: 10.191.104.225 | D4776: 00:21:28:FB:88:20 | F4776: NO | G4776: NO | H4776: 0 | I4776: 0 | J4776: =IF(F4776="SI", "NA", IF(OR(E4776="Oracle Solaris", E4776="Windows Server 2008 R2", E4776="Windows Server 2003 R2", E4776="SunOS 10", E4776="SunOS 11.1", E4776="SunOS 11.2", E4776="SunOS 11.3", E4776="IBM AIX 6.1", E4776="IBM AIX 7.1", E4776="IBM AIX 7.2", E4776="IBM AIX 5.3", E4776="SunOS 9", E4776="SunOS 11.4.23.69.3", E4776="SunOS 11.0", E4776="SunOS 11.4", E4776="SunOS 11.4.0.15.0"), "Cortex not supported", "NA"))
A4777: 4772 | B4777: IXTAI2 | C4777: 10.191.129.184 | D4777: 00:21:28:C0:A2:92 | F4777: NO | G4777: NO | H4777: 0 | I4777: 0 | J4777: =IF(F4777="SI", "NA", IF(OR(E4777="Oracle Solaris", E4777="Windows Server 2008 R2", E4777="Windows Server 2003 R2", E4777="SunOS 10", E4777="SunOS 11.1", E4777="SunOS 11.2", E4777="SunOS 11.3", E4777="IBM AIX 6.1", E4777="IBM AIX 7.1", E4777="IBM AIX 7.2", E4777="IBM AIX 5.3", E4777="SunOS 9", E4777="SunOS 11.4.23.69.3", E4777="SunOS 11.0", E4777="SunOS 11.4", E4777="SunOS 11.4.0.15.0"), "Cortex not supported", "NA"))
A4778: 4773 | B4778: IXTAI1 | C4778: 10.191.129.167 | D4778: 00:21:28:C0:A5:74 | F4778: NO | G4778: NO | H4778: 0 | I4778: 0 | J4778: =IF(F4778="SI", "NA", IF(OR(E4778="Oracle Solaris", E4778="Windows Server 2008 R2", E4778="Windows Server 2003 R2", E4778="SunOS 10", E4778="SunOS 11.1", E4778="SunOS 11.2", E4778="SunOS 11.3", E4778="IBM AIX 6.1", E4778="IBM AIX 7.1", E4778="IBM AIX 7.2", E4778="IBM AIX 5.3", E4778="SunOS 9", E4778="SunOS 11.4.23.69.3", E4778="SunOS 11.0", E4778="SunOS 11.4", E4778="SunOS 11.4.0.15.0"), "Cortex not supported", "NA"))
A4779: 4774 | B4779: IXTAF4 | C4779: 10.119.144.28 | D4779: 00:21:28:A3:19:64 | F4779: NO | G4779: NO | H4779: 0 | I4779: 0 | J4779: =IF(F4779="SI", "NA", IF(OR(E4779="Oracle Solaris", E4779="Windows Server 2008 R2", E4779="Windows Server 2003 R2", E4779="SunOS 10", E4779="SunOS 11.1", E4779="SunOS 11.2", E4779="SunOS 11.3", E4779="IBM AIX 6.1", E4779="IBM AIX 7.1", E4779="IBM AIX 7.2", E4779="IBM AIX 5.3", E4779="SunOS 9", E4779="SunOS 11.4.23.69.3", E4779="SunOS 11.0", E4779="SunOS 11.4", E4779="SunOS 11.4.0.15.0"), "Cortex not supported", "NA"))
A4780: 4775 | B4780: IXTAF3 | C4780: 10.119.144.20 | D4780: 00:21:28:8E:1D:0A | F4780: NO | G4780: NO | H4780: 0 | I4780: 0 | J4780: =IF(F4780="SI", "NA", IF(OR(E4780="Oracle Solaris", E4780="Windows Server 2008 R2", E4780="Windows Server 2003 R2", E4780="SunOS 10", E4780="SunOS 11.1", E4780="SunOS 11.2", E4780="SunOS 11.3", E4780="IBM AIX 6.1", E4780="IBM AIX 7.1", E4780="IBM AIX 7.2", E4780="IBM AIX 5.3", E4780="SunOS 9", E4780="SunOS 11.4.23.69.3", E4780="SunOS 11.0", E4780="SunOS 11.4", E4780="SunOS 11.4.0.15.0"), "Cortex not supported", "NA"))
A4781: 4776 | B4781: IXTAF2 | C4781: 10.191.129.151 | D4781: 00:21:28:C0:99:EC | F4781: NO | G4781: NO | H4781: 0 | I4781: 0 | J4781: =IF(F4781="SI", "NA", IF(OR(E4781="Oracle Solaris", E4781="Windows Server 2008 R2", E4781="Windows Server 2003 R2", E4781="SunOS 10", E4781="SunOS 11.1", E4781="SunOS 11.2", E4781="SunOS 11.3", E4781="IBM AIX 6.1", E4781="IBM AIX 7.1", E4781="IBM AIX 7.2", E4781="IBM AIX 5.3", E4781="SunOS 9", E4781="SunOS 11.4.23.69.3", E4781="SunOS 11.0", E4781="SunOS 11.4", E4781="SunOS 11.4.0.15.0"), "Cortex not supported", "NA"))
A4782: 4777 | B4782: IXTAF1 | C4782: 10.191.129.136 | D4782: 00:21:28:C0:A2:D4 | F4782: NO | G4782: NO | H4782: 0 | I4782: 0 | J4782: =IF(F4782="SI", "NA", IF(OR(E4782="Oracle Solaris", E4782="Windows Server 2008 R2", E4782="Windows Server 2003 R2", E4782="SunOS 10", E4782="SunOS 11.1", E4782="SunOS 11.2", E4782="SunOS 11.3", E4782="IBM AIX 6.1", E4782="IBM AIX 7.1", E4782="IBM AIX 7.2", E4782="IBM AIX 5.3", E4782="SunOS 9", E4782="SunOS 11.4.23.69.3", E4782="SunOS 11.0", E4782="SunOS 11.4", E4782="SunOS 11.4.0.15.0"), "Cortex not supported", "NA"))
A4783: 4778 | B4783: UXINGHDR5 | C4783: 10.119.167.224 | D4783: 00:14:4F:FB:4B:36 | F4783: NO | G4783: NO | H4783: 0 | I4783: 0 | J4783: =IF(F4783="SI", "NA", IF(OR(E4783="Oracle Solaris", E4783="Windows Server 2008 R2", E4783="Windows Server 2003 R2", E4783="SunOS 10", E4783="SunOS 11.1", E4783="SunOS 11.2", E4783="SunOS 11.3", E4783="IBM AIX 6.1", E4783="IBM AIX 7.1", E4783="IBM AIX 7.2", E4783="IBM AIX 5.3", E4783="SunOS 9", E4783="SunOS 11.4.23.69.3", E4783="SunOS 11.0", E4783="SunOS 11.4", E4783="SunOS 11.4.0.15.0"), "Cortex not supported", "NA"))
A4784: 4779 | B4784: UXINGHDR3 | C4784: 10.119.167.221 | D4784: 00:14:4F:F9:AE:35 | F4784: NO | G4784: NO | H4784: 0 | I4784: 0 | J4784: =IF(F4784="SI", "NA", IF(OR(E4784="Oracle Solaris", E4784="Windows Server 2008 R2", E4784="Windows Server 2003 R2", E4784="SunOS 10", E4784="SunOS 11.1", E4784="SunOS 11.2", E4784="SunOS 11.3", E4784="IBM AIX 6.1", E4784="IBM AIX 7.1", E4784="IBM AIX 7.2", E4784="IBM AIX 5.3", E4784="SunOS 9", E4784="SunOS 11.4.23.69.3", E4784="SunOS 11.0", E4784="SunOS 11.4", E4784="SunOS 11.4.0.15.0"), "Cortex not supported", "NA"))
A4785: 4780 | B4785: ITHVRHANDARAP01.MYTELCEL.COM | C4785: 10.59.230.234 200.68.130.150 | D4785: 56:6F:3C:FD:02:C4 | E4785: Linux Red Hat 7.9 | F4785: SI | G4785: NO | H4785: 16 | I4785: 0 | J4785: =IF(F4785="SI", "NA", IF(OR(E4785="Oracle Solaris", E4785="Windows Server 2008 R2", E4785="Windows Server 2003 R2", E4785="SunOS 10", E4785="SunOS 11.1", E4785="SunOS 11.2", E4785="SunOS 11.3", E4785="IBM AIX 6.1", E4785="IBM AIX 7.1", E4785="IBM AIX 7.2", E4785="IBM AIX 5.3", E4785="SunOS 9", E4785="SunOS 11.4.23.69.3", E4785="SunOS 11.0", E4785="SunOS 11.4", E4785="SunOS 11.4.0.15.0"), "Cortex not supported", "NA"))
A4786: 4781 | B4786: ITHVRHANDARAP02.MYTELCEL.COM | C4786: 10.59.230.235 200.68.130.132 | D4786: 56:6F:3C:FD:02:CD | E4786: Linux Red Hat 7.9 | F4786: SI | G4786: NO | H4786: 13 | I4786: 0 | J4786: =IF(F4786="SI", "NA", IF(OR(E4786="Oracle Solaris", E4786="Windows Server 2008 R2", E4786="Windows Server 2003 R2", E4786="SunOS 10", E4786="SunOS 11.1", E4786="SunOS 11.2", E4786="SunOS 11.3", E4786="IBM AIX 6.1", E4786="IBM AIX 7.1", E4786="IBM AIX 7.2", E4786="IBM AIX 5.3", E4786="SunOS 9", E4786="SunOS 11.4.23.69.3", E4786="SunOS 11.0", E4786="SunOS 11.4", E4786="SunOS 11.4.0.15.0"), "Cortex not supported", "NA"))
A4787: 4782 | B4787: ITHVIBACTDAAPBD01 | C4787: 10.54.133.8 | D4787: B2:1A:75:6A:6B:09 | E4787: IBM AIX 7.2 | F4787: NO | G4787: NO | H4787: 0 | I4787: 0 | J4787: =IF(F4787="SI", "NA", IF(OR(E4787="Oracle Solaris", E4787="Windows Server 2008 R2", E4787="Windows Server 2003 R2", E4787="SunOS 10", E4787="SunOS 11.1", E4787="SunOS 11.2", E4787="SunOS 11.3", E4787="IBM AIX 6.1", E4787="IBM AIX 7.1", E4787="IBM AIX 7.2", E4787="IBM AIX 5.3", E4787="SunOS 9", E4787="SunOS 11.4.23.69.3", E4787="SunOS 11.0", E4787="SunOS 11.4", E4787="SunOS 11.4.0.15.0"), "Cortex not supported", "NA"))
A4788: 4783 | B4788: ITHVRHANDARAP03.MYTELCEL.COM | C4788: 10.59.230.236 200.68.130.151 | D4788: 56:6F:3C:FD:02:C5 | E4788: Linux Red Hat 7.9 | F4788: SI | G4788: NO | H4788: 13 | I4788: 0 | J4788: =IF(F4788="SI", "NA", IF(OR(E4788="Oracle Solaris", E4788="Windows Server 2008 R2", E4788="Windows Server 2003 R2", E4788="SunOS 10", E4788="SunOS 11.1", E4788="SunOS 11.2", E4788="SunOS 11.3", E4788="IBM AIX 6.1", E4788="IBM AIX 7.1", E4788="IBM AIX 7.2", E4788="IBM AIX 5.3", E4788="SunOS 9", E4788="SunOS 11.4.23.69.3", E4788="SunOS 11.0", E4788="SunOS 11.4", E4788="SunOS 11.4.0.15.0"), "Cortex not supported", "NA"))
A4789: 4784 | B4789: ITHHWMED1DE2 | C4789: 10.119.249.165 172.16.0.9 200.68.130.131 | D4789: FA:16:3E:98:73:74 FA:16:3E:AC:AB:82 | E4789: Linux Red Hat 7.7 | F4789: SI | G4789: NO | H4789: 104 | I4789: 0 | J4789: =IF(F4789="SI", "NA", IF(OR(E4789="Oracle Solaris", E4789="Windows Server 2008 R2", E4789="Windows Server 2003 R2", E4789="SunOS 10", E4789="SunOS 11.1", E4789="SunOS 11.2", E4789="SunOS 11.3", E4789="IBM AIX 6.1", E4789="IBM AIX 7.1", E4789="IBM AIX 7.2", E4789="IBM AIX 5.3", E4789="SunOS 9", E4789="SunOS 11.4.23.69.3", E4789="SunOS 11.0", E4789="SunOS 11.4", E4789="SunOS 11.4.0.15.0"), "Cortex not supported", "NA"))
A4790: 4785 | B4790: ITHFIBDISTABD01 | C4790: 10.54.133.5 | D4790: 34:80:0D:99:05:E8 | E4790: IBM AIX 7.2 | F4790: NO | G4790: SI | H4790: 0 | I4790: 0 | J4790: =IF(F4790="SI", "NA", IF(OR(E4790="Oracle Solaris", E4790="Windows Server 2008 R2", E4790="Windows Server 2003 R2", E4790="SunOS 10", E4790="SunOS 11.1", E4790="SunOS 11.2", E4790="SunOS 11.3", E4790="IBM AIX 6.1", E4790="IBM AIX 7.1", E4790="IBM AIX 7.2", E4790="IBM AIX 5.3", E4790="SunOS 9", E4790="SunOS 11.4.23.69.3", E4790="SunOS 11.0", E4790="SunOS 11.4", E4790="SunOS 11.4.0.15.0"), "Cortex not supported", "NA"))
A4791: 4786 | B4791: SFV1ICTD01 | C4791: 10.119.198.19 200.68.130.151 | D4791: 56:6F:3C:FD:01:B0 | E4791: Linux Red Hat 6.6 | F4791: SI | G4791: NO | H4791: 129 | I4791: 0 | J4791: =IF(F4791="SI", "NA", IF(OR(E4791="Oracle Solaris", E4791="Windows Server 2008 R2", E4791="Windows Server 2003 R2", E4791="SunOS 10", E4791="SunOS 11.1", E4791="SunOS 11.2", E4791="SunOS 11.3", E4791="IBM AIX 6.1", E4791="IBM AIX 7.1", E4791="IBM AIX 7.2", E4791="IBM AIX 5.3", E4791="SunOS 9", E4791="SunOS 11.4.23.69.3", E4791="SunOS 11.0", E4791="SunOS 11.4", E4791="SunOS 11.4.0.15.0"), "Cortex not supported", "NA"))
A4792: 4787 | B4792: ITHVY1VM6 | C4792: 10.119.224.137 | D4792: 28:80:23:A5:37:DC 28:80:23:A5:37:DD 28:80:23:A5:37:DE 28:80:23:A5:37:DF 28:80:23:B2:A1:1C 28:80:23:B2:A1:1D 28:80:23:B2:A1:1E 28:80:23:B2:A1:1F 28:80:23:B2:A3:94 28:80:23:B2:A3:96 94:57:A5:59:F3:04 94:57:A5:59:F3:05 94:57:A5:59:F3:06 94:57:A5:59:F3:07 | E4792: Linux Red Hat 7.1 | F4792: NO | G4792: SI | H4792: 0 | I4792: 0 | J4792: =IF(F4792="SI", "NA", IF(OR(E4792="Oracle Solaris", E4792="Windows Server 2008 R2", E4792="Windows Server 2003 R2", E4792="SunOS 10", E4792="SunOS 11.1", E4792="SunOS 11.2", E4792="SunOS 11.3", E4792="IBM AIX 6.1", E4792="IBM AIX 7.1", E4792="IBM AIX 7.2", E4792="IBM AIX 5.3", E4792="SunOS 9", E4792="SunOS 11.4.23.69.3", E4792="SunOS 11.0", E4792="SunOS 11.4", E4792="SunOS 11.4.0.15.0"), "Cortex not supported", "NA"))
A4793: 4788 | B4793: ITHVY1VM5 | C4793: 10.119.224.136 | D4793: 28:80:23:A5:64:00 28:80:23:A5:64:01 28:80:23:A5:64:02 28:80:23:A5:64:03 28:80:23:B2:A4:C4 28:80:23:B2:A4:C6 28:80:23:B2:C1:60 28:80:23:B2:C1:61 28:80:23:B2:C1:62 28:80:23:B2:C1:63 30:E1:71:6F:48:80 30:E1:71:6F:48:81 30:E1:71:6F:48:82 30:E1:71:6F:48:83 98:F2:B3:2A:45:78 98:F2:B3:2A:45:7A 98:F2:B3:2A:45:7B | E4793: Linux Red Hat 7.9 | F4793: NO | G4793: SI | H4793: 0 | I4793: 0 | J4793: =IF(F4793="SI", "NA", IF(OR(E4793="Oracle Solaris", E4793="Windows Server 2008 R2", E4793="Windows Server 2003 R2", E4793="SunOS 10", E4793="SunOS 11.1", E4793="SunOS 11.2", E4793="SunOS 11.3", E4793="IBM AIX 6.1", E4793="IBM AIX 7.1", E4793="IBM AIX 7.2", E4793="IBM AIX 5.3", E4793="SunOS 9", E4793="SunOS 11.4.23.69.3", E4793="SunOS 11.0", E4793="SunOS 11.4", E4793="SunOS 11.4.0.15.0"), "Cortex not supported", "NA"))
A4794: 4789 | B4794: BROKER-VM | C4794: 10.119.111.40 172.17.64.1 | D4794: 00:50:56:AC:93:09 1E:AC:31:0A:FA:63 | E4794: Linux Ubuntu 20.04.6 | F4794: NO | G4794: NO | H4794: 0 | I4794: 0 | J4794: =IF(F4794="SI", "NA", IF(OR(E4794="Oracle Solaris", E4794="Windows Server 2008 R2", E4794="Windows Server 2003 R2", E4794="SunOS 10", E4794="SunOS 11.1", E4794="SunOS 11.2", E4794="SunOS 11.3", E4794="IBM AIX 6.1", E4794="IBM AIX 7.1", E4794="IBM AIX 7.2", E4794="IBM AIX 5.3", E4794="SunOS 9", E4794="SunOS 11.4.23.69.3", E4794="SunOS 11.0", E4794="SunOS 11.4", E4794="SunOS 11.4.0.15.0"), "Cortex not supported", "NA"))
A4795: 4790 | B4795: BROKER-VM | C4795: 10.119.111.21 172.17.64.1 | D4795: 00:50:56:AC:21:A7 12:0B:AD:8C:9F:75 | E4795: Linux Ubuntu 20.04.6 | F4795: NO | G4795: NO | H4795: 0 | I4795: 0 | J4795: =IF(F4795="SI", "NA", IF(OR(E4795="Oracle Solaris", E4795="Windows Server 2008 R2", E4795="Windows Server 2003 R2", E4795="SunOS 10", E4795="SunOS 11.1", E4795="SunOS 11.2", E4795="SunOS 11.3", E4795="IBM AIX 6.1", E4795="IBM AIX 7.1", E4795="IBM AIX 7.2", E4795="IBM AIX 5.3", E4795="SunOS 9", E4795="SunOS 11.4.23.69.3", E4795="SunOS 11.0", E4795="SunOS 11.4", E4795="SunOS 11.4.0.15.0"), "Cortex not supported", "NA"))
A4796: 4791 | B4796: ITHVHPEDALVC01 | C4796: 10.54.137.234 | D4796: 00:0C:29:DE:3D:05 | E4796: Linux Photon OS (64-bit) | F4796: NO | G4796: NO | H4796: 0 | I4796: 0 | J4796: =IF(F4796="SI", "NA", IF(OR(E4796="Oracle Solaris", E4796="Windows Server 2008 R2", E4796="Windows Server 2003 R2", E4796="SunOS 10", E4796="SunOS 11.1", E4796="SunOS 11.2", E4796="SunOS 11.3", E4796="IBM AIX 6.1", E4796="IBM AIX 7.1", E4796="IBM AIX 7.2", E4796="IBM AIX 5.3", E4796="SunOS 9", E4796="SunOS 11.4.23.69.3", E4796="SunOS 11.0", E4796="SunOS 11.4", E4796="SunOS 11.4.0.15.0"), "Cortex not supported", "NA"))
... A4799: 4794 | B4799: ITHFZTTANGRPOTB1E | C4799: 10.152.27.45 | D4799: B4:96:91:AA:2F:E2 | E4799: Linux Red Hat 7.6 | F4799: NO | G4799: NO | H4799: 0 | I4799: 0 | J4799: =IF(F4799="SI", "NA", IF(OR(E4799="Oracle Solaris", E4799="Windows Server 2008 R2", E4799="Windows Server 2003 R2", E4799="SunOS 10", E4799="SunOS 11.1", E4799="SunOS 11.2", E4799="SunOS 11.3", E4799="IBM AIX 6.1", E4799="IBM AIX 7.1", E4799="IBM AIX 7.2", E4799="IBM AIX 5.3", E4799="SunOS 9", E4799="SunOS 11.4.23.69.3", E4799="SunOS 11.0", E4799="SunOS 11.4", E4799="SunOS 11.4.0.15.0"), "Cortex not supported", "NA"))
A4800: 4795 | B4800: ITHFHPTMIPLVCP101 | C4800: 10.119.78.76 | D4800: EE:CA:39:10:00:03 | F4800: NO | G4800: NO | H4800: 0 | I4800: 0 | J4800: =IF(F4800="SI", "NA", IF(OR(E4800="Oracle Solaris", E4800="Windows Server 2008 R2", E4800="Windows Server 2003 R2", E4800="SunOS 10", E4800="SunOS 11.1", E4800="SunOS 11.2", E4800="SunOS 11.3", E4800="IBM AIX 6.1", E4800="IBM AIX 7.1", E4800="IBM AIX 7.2", E4800="IBM AIX 5.3", E4800="SunOS 9", E4800="SunOS 11.4.23.69.3", E4800="SunOS 11.0", E4800="SunOS 11.4", E4800="SunOS 11.4.0.15.0"), "Cortex not supported", "NA"))
A4801: 4796 | B4801: ITHFHPTMIPLVCP103 | C4801: 10.119.78.78 | D4801: EE:CA:39:10:00:16 | F4801: NO | G4801: NO | H4801: 0 | I4801: 0 | J4801: =IF(F4801="SI", "NA", IF(OR(E4801="Oracle Solaris", E4801="Windows Server 2008 R2", E4801="Windows Server 2003 R2", E4801="SunOS 10", E4801="SunOS 11.1", E4801="SunOS 11.2", E4801="SunOS 11.3", E4801="IBM AIX 6.1", E4801="IBM AIX 7.1", E4801="IBM AIX 7.2", E4801="IBM AIX 5.3", E4801="SunOS 9", E4801="SunOS 11.4.23.69.3", E4801="SunOS 11.0", E4801="SunOS 11.4", E4801="SunOS 11.4.0.15.0"), "Cortex not supported", "NA"))
...

Sheet Inventario - EOL
A3: Servidores EOL IXTLAHUACA - Inventario
A4: No | B4: Hostname | C4: Dir IP | D4: MAC | E4: SISTEMA OPERATIVO | F4: Cortex | G4: Virtual Patching | H4: Software EoL
A6: 1 | B6: ITHVHWIPAWPAP01 | C6: 10.59.195.190 200.68.130.132 | D6: 00:50:56:81:0E:86 | E6: Windows Server 2022 | F6: SI | G6: SI | H6: 2
A7: 2 | B7: ITHHWHUEPRO18 | C7: 10.119.249.107 200.68.130.151 | D7: FA:16:3E:12:A4:00 | E7: Linux Red Hat 7.9 | F7: SI | G7: SI | H7: 14
A8: 3 | B8: ITHVVWRPADRBD02 | C8: 10.59.240.64 200.68.130.150 | D8: 00:50:56:81:1B:EE | E8: Linux Red Hat 8.10 | F8: SI | G8: SI | H8: 4
A9: 4 | B9: IXVPECIAPS001 | C9: 10.191.33.94 200.68.130.150 | D9: 00:50:56:86:A8:23 | E9: Linux Red Hat 7.9 | F9: SI | G9: SI | H9: 11
A10: 5 | B10: IXVPECIAPS002 | C10: 10.191.33.95 200.68.130.150 | D10: 00:50:56:86:B1:FC | E10: Linux Red Hat 7.9 | F10: SI | G10: SI | H10: 9
A11: 6 | B11: IXVPECIAPS003 | C11: 10.191.33.96 200.68.130.151 | D11: 00:50:56:86:A3:4E | E11: Linux Red Hat 7.9 | F11: SI | G11: SI | H11: 6
A12: 7 | B12: IXVPECIAPS004 | C12: 10.191.33.97 200.68.130.131 | D12: 00:50:56:86:8C:89 | E12: Linux Red Hat 7.9 | F12: SI | G12: SI | H12: 5
A13: 8 | B13: ITHVHWPSPWPAP02 | C13: 10.152.30.33 200.68.130.132 | D13: 00:50:56:81:E0:4E | E13: Windows Server 2022 | F13: SI | G13: SI | H13: 1
A14: 9 | B14: ITHVHWPSPWPAP01 | C14: 10.152.30.32 200.68.130.132 | D14: 00:50:56:81:F1:05 | E14: Windows Server 2022 | F14: SI | G14: SI | H14: 4
A15: 10 | B15: ITHVHWPSPWPAP03 | C15: 10.152.30.34 200.68.130.132 | D15: 00:50:56:81:3E:2A | E15: Windows Server 2022 | F15: SI | G15: SI | H15: 1
A16: 11 | B16: ITHVHWMPPWPAP02 | C16: 10.152.75.68 200.68.130.132 | D16: 00:50:56:81:B7:64 | E16: Windows Server 2022 | F16: SI | G16: SI | H16: 2
A17: 12 | B17: ITHVVMSVDAWAP01 | C17: 10.152.75.58 200.68.130.131 | D17: 00:50:56:81:5A:B4 | E17: Windows Server 2022 | F17: SI | G17: SI | H17: 1
... A4381: 4376 | B4381: ITHVHWIVRSFILE01 | C4381: 10.152.65.43 | D4381: 02:42:59:83:A9:BF 52:C9:63:3E:67:67 FA:16:3E:4A:D8:70 FA:16:3E:EB:D5:86 | E4381: Linux openSUSE 12.5 | F4381: NO | G4381: NO | H4381: 16
A4382: 4377 | B4382: ITHVHPZR58LAP01 | C4382: 10.191.211.165 | D4382: 00:50:56:AC:97:15 | F4382: NO | G4382: NO | H4382: 28
A4383: 4378 | B4383: ITHVVW0546RBD01 | C4383: 10.152.148.180 200.68.130.131 | D4383: 00:50:56:81:18:78 | E4383: Linux Red Hat 9.4 | F4383: SI | G4383: NO | H4383: 1
A4384: 4379 | B4384: ITHVVW0546RAP01 | C4384: 10.119.179.146 10.119.241.140 10.152.148.181 10.54.0.18 192.168.32.175 200.68.130.131 | D4384: 00:50:56:81:33:80 00:50:56:81:8B:36 00:50:56:81:BF:70 00:50:56:81:DB:95 00:50:56:81:E0:B6 | E4384: Linux Red Hat 9.4 | F4384: SI | G4384: NO | H4384: 1
A4385: 4380 | B4385: ITHVRHPGSURBD01 | C4385: 10.59.240.141 | D4385: 56:6F:9F:00:02:88 | E4385: Linux Red Hat 8.6 | F4385: NO | G4385: NO | H4385: 1
A4386: 4381 | B4386: ITHVVWOBMORBD01 | C4386: 10.152.106.188 | D4386: 00:50:56:81:B8:25 | E4386: Linux Red Hat 8.10 | F4386: NO | G4386: NO | H4386: 1
A4387: 4382 | B4387: ITHVVWTEACRAP01 | C4387: 10.152.105.249 | D4387: 00:50:56:81:2C:ED | E4387: Linux Red Hat 8.8 | F4387: NO | G4387: NO | H4387: 1
A4388: 4383 | B4388: ITHFHWCBSPSBLBD03 | C4388: 10.59.174.226 10.59.174.40 10.59.179.40 10.59.220.226 10.59.220.40 10.59.36.226 10.59.36.40 200.68.130.132 | D4388: 28:68:D2:D2:35:21 28:68:D2:D2:35:23 CC:B1:82:CD:C7:B6 | E4388: Linux openSUSE 12.5 | F4388: SI | G4388: NO | H4388: 2
A4389: 4384 | B4389: ITHFHWCBSPSBLBD05 | C4389: 10.59.174.232 10.59.174.42 10.59.179.42 10.59.220.232 10.59.220.42 10.59.36.232 10.59.36.42 200.68.130.132 | D4389: 28:68:D2:D2:35:F9 28:68:D2:D2:35:FB CC:B1:82:CD:C8:11 | E4389: Linux openSUSE 12.5 | F4389: SI | G4389: NO | H4389: 2
A4390: 4385 | B4390: ITHFHWCBSPSBLBD11 | C4390: 10.59.174.225 10.59.174.48 10.59.179.48 10.59.220.225 10.59.220.48 10.59.36.225 10.59.36.48 200.68.130.131 | D4390: 28:68:D2:D2:30:D5 28:68:D2:D2:30:D7 44:22:7C:29:E6:64 | E4390: Linux openSUSE 12.5 | F4390: SI | G4390: NO | H4390: 3
A4391: 4386 | B4391: ITHFHWCBSPSBLBD10 | C4391: 10.59.174.233 10.59.174.47 10.59.179.47 10.59.220.233 10.59.220.47 10.59.36.233 10.59.36.47 200.68.130.150 | D4391: 28:68:D2:D2:36:B5 28:68:D2:D2:36:B7 CC:B1:82:CD:C7:CB | E4391: Linux openSUSE 12.5 | F4391: SI | G4391: NO | H4391: 1
A4392: 4387 | B4392: ITHFHWCBSDSUSBD01 | C4392: 10.152.10.32 10.152.16.32 10.152.17.32 10.152.19.32 200.68.130.150 | D4392: 00:E4:06:CC:36:4C 28:68:D2:AD:79:AC 28:68:D2:AD:79:AE | E4392: Linux openSUSE 12.5 | F4392: SI | G4392: NO | H4392: 1
A4393: 4388 | B4393: ITHFHWCBSPSBLBD14 | C4393: 10.59.174.227 10.59.174.51 10.59.179.51 10.59.220.227 10.59.220.51 10.59.36.227 10.59.36.51 200.68.130.150 | D4393: 28:68:D2:D2:34:15 28:68:D2:D2:34:17 44:22:7C:29:E6:B8 | E4393: Linux openSUSE 12.5 | F4393: SI | G4393: NO | H4393: 1
A4394: 4389 | B4394: ITHFHWCBSDSBMBD01 | C4394: 10.152.10.31 10.152.16.31 10.152.17.31 10.152.19.31 200.68.130.130 | D4394: 28:68:D2:D2:32:51 28:68:D2:D2:32:53 44:22:7C:29:E4:96 | E4394: Linux openSUSE 12.5 | F4394: SI | G4394: NO | H4394: 3
... A5197: 5192 | B5197: IXVPWINAPS005.TELCEL.NET | C5197: 10.59.26.253 10.59.32.253 | D5197: FA:16:3E:17:68:45 FA:16:3E:C3:50:A5 | E5197: Windows Server 2016 | F5197: NO | G5197: NO | H5197: 5
A5198: 5193 | B5198: EVAKPISVRM-8 | C5198: 10.59.177.81 | D5198: FA:16:3E:26:E1:5B FA:16:3E:2E:14:9A FA:16:3E:61:56:0C FA:16:3E:DB:72:9A | F5198: NO | G5198: NO | H5198: 5
A5199: 5194 | B5199: ITHFHWRHV2LCN01.TELCELCLOUD.DT | C5199: 10.59.200.141 | D5199: E0:00:84:AC:1F:95 | E5199: Linux Red Hat 8.6 | F5199: NO | G5199: NO | H5199: 4
A5200: 5195 | B5200: ITHFHWRHV2LCN05.TELCELCLOUD.DT | C5200: 10.59.200.145 | D5200: E0:00:84:AC:1F:B5 | E5200: Linux Red Hat 8.6 | F5200: NO | G5200: NO | H5200: 4
A5201: 5196 | B5201: ITHFHWRHV2LCN03.TELCELCLOUD.DT | C5201: 10.59.200.143 | D5201: E0:00:84:AC:1F:35 | E5201: Linux Red Hat 8.6 | F5201: NO | G5201: NO | H5201: 4
A5202: 5197 | B5202: ITHFHWRHV2LCN06.TELCELCLOUD.DT | C5202: 10.59.200.146 | D5202: E0:00:84:AC:1F:D1 | E5202: Linux Red Hat 8.6 | F5202: NO | G5202: NO | H5202: 4
A5203: 5198 | B5203: ITHFHWRHV2LCN04.TELCELCLOUD.DT | C5203: 10.59.200.144 | D5203: E0:00:84:AC:1F:3D | E5203: Linux Red Hat 8.6 | F5203: NO | G5203: NO | H5203: 4
A5204: 5199 | B5204: ITHHWCGRAF01 | C5204: 10.119.249.53 | D5204: FA:16:3E:B6:B5:65 | E5204: Linux Red Hat 7.7 | F5204: NO | G5204: NO | H5204: 5
A5205: 5200 | B5205: EVAKPISVRM-7 | C5205: 10.59.175.107 | D5205: FA:16:3E:45:F3:CA FA:16:3E:6E:4D:DD FA:16:3E:79:CF:FD FA:16:3E:86:C8:2B | F5205: NO | G5205: NO | H5205: 6
A5206: 5201 | B5206: ITHVRHNUASRPAP03 | C5206: 10.152.74.165 | D5206: 56:6F:9F:00:00:DD | E5206: Linux Red Hat 8.10 | F5206: NO | G5206: NO | H5206: 1
A5207: 5202 | B5207: ITHHWPP1CRHV06.TELCELCLOUD.DT | C5207: 10.119.78.131 | D5207: 04:88:5F:CA:AB:12 04:88:5F:CA:AB:13 32:2F:BA:3E:10:3C 8C:FD:18:B7:EF:C0 8C:FD:18:B7:EF:C2 BA:19:3E:C1:2F:BC | E5207: Linux Red Hat 8.6 | F5207: NO | G5207: NO | H5207: 4
A5208: 5203 | B5208: ITHHWPP1CRHV04.TELCELCLOUD.DT | C5208: 10.119.78.126 | D5208: 8C:FD:18:B7:EF:34 8C:FD:18:B7:EF:36 98:35:ED:CE:1E:59 98:35:ED:CE:1E:5A BE:35:AD:B7:8B:AE DA:79:D2:15:08:44 | E5208: Linux Red Hat 8.6 | F5208: NO | G5208: NO | H5208: 4
...

Sheet Inventario No Identificados
A3: No identificados (Servidores) - Inventario
A4: Adaptadores | B4: IPs | C4: MACs | D4: Manufacturer | E4: Clasificacion
A5: cisco_apic_adapter nagios_xi_adapter nagios_xi_adapter | B5: 10.119.234.19 | C5: 00:10:E0:B6:67:C2 | D5: (Oracle Corporation) | E5: Fabricantes/Administradores de servidores virtuales y soluciones de virtualización
A6: cisco_apic_adapter nagios_xi_adapter nagios_xi_adapter | B6: 10.119.234.20 | C6: 00:10:E0:94:BF:10 | D6: (Oracle Corporation) | E6: Fabricantes/Administradores de servidores virtuales y soluciones de virtualización
A7: cisco_apic_adapter cisco_apic_adapter wazuh_adapter | B7: 10.59.25.132 | C7: FA:16:3E:29:FC:02 | D7: (Huawei Technologies Co.,Ltd) | E7: Fabricantes de servidores físicos
A8: cisco_apic_adapter tenable_security_center_adapter | B8: 10.59.32.233 | C8: 80:69:33:FE:16:49 | D8: (Huawei Technologies Co.,Ltd) | E8: Fabricantes de servidores físicos
A9: cisco_apic_adapter cisco_apic_adapter wazuh_adapter | B9: 10.59.25.151 | C9: FA:16:3E:E6:01:9D | D9: (Huawei Technologies Co.,Ltd) | E9: Fabricantes de servidores físicos
A10: cisco_apic_adapter nessus_adapter | B10: 10.119.105.19 | C10: 28:7B:09:C3:BC:AA | D10: (zte corporation) | E10: Fabricantes de servidores físicos
A11: cisco_apic_adapter cisco_apic_adapter wazuh_adapter | B11: 10.59.25.190 | C11: FA:16:3E:58:05:3A | D11: (Huawei Technologies Co.,Ltd) | E11: Fabricantes de servidores físicos
A12: cisco_apic_adapter cisco_apic_adapter wazuh_adapter | B12: 10.59.25.220 | C12: FA:16:3E:16:A4:62 | D12: (Huawei Technologies Co.,Ltd) | E12: Fabricantes de servidores físicos
A13: cisco_apic_adapter cisco_apic_adapter wazuh_adapter | B13: 10.59.25.235 | C13: FA:16:3E:3E:C1:49 | D13: (Huawei Technologies Co.,Ltd) | E13: Fabricantes de servidores físicos
A14: cisco_apic_adapter cisco_apic_adapter wazuh_adapter | B14: 10.59.25.152 | C14: FA:16:3E:49:3E:CE | D14: (Huawei Technologies Co.,Ltd) | E14: Fabricantes de servidores físicos
A15: cisco_apic_adapter cisco_apic_adapter wazuh_adapter | B15: 10.59.25.130 | C15: FA:16:3E:0C:8C:B0 | D15: (Huawei Technologies Co.,Ltd) | E15: Fabricantes de servidores físicos
... A83: cisco_apic_adapter cisco_apic_adapter cisco_apic_adapter cisco_apic_adapter | B83: 10.152.0.9 | C83: 44:22:7C:18:DE:12 | D83: (Huawei Technologies Co.,Ltd) | E83: Fabricantes de servidores físicos
A84: cisco_apic_adapter | C84: F0:3F:95:96:0A:90 | D84: (Huawei Technologies Co.,Ltd) | E84: Fabricantes de servidores físicos
A85: cisco_apic_adapter | B85: 10.59.20.43 | C85: 80:69:33:62:F1:35 | D85: (Huawei Technologies Co.,Ltd) | E85: Fabricantes de servidores físicos
A86: cisco_apic_adapter cisco_apic_adapter cisco_apic_adapter cisco_apic_adapter | B86: 10.152.0.18 | C86: CC:B1:82:9B:56:3D | D86: (Huawei Technologies Co.,Ltd) | E86: Fabricantes de servidores físicos
A87: cisco_apic_adapter cisco_apic_adapter cisco_apic_adapter cisco_apic_adapter cisco_apic_adapter | B87: 10.59.152.228 | C87: 80:30:E0:05:D3:00 | D87: (Hewlett Packard Enterprise) | E87: Fabricantes de servidores físicos
A88: cisco_apic_adapter | B88: 10.119.104.9 | C88: 74:4A:A4:0B:1B:F4 | D88: (zte corporation) | E88: Fabricantes de servidores físicos
A89: cisco_apic_adapter | B89: 10.191.144.74 10.191.144.76 | C89: 4C:1F:CC:A9:C0:13 | D89: (Huawei Technologies Co.,Ltd) | E89: Fabricantes de servidores físicos
A90: cisco_apic_adapter cisco_apic_adapter cisco_apic_adapter cisco_apic_adapter | B90: 10.59.152.214 | C90: 80:30:E0:05:AF:20 | D90: (Hewlett Packard Enterprise) | E90: Fabricantes de servidores físicos
A91: cisco_apic_adapter | C91: 20:67:7C:19:D3:79 | D91: (Hewlett Packard Enterprise) | E91: Fabricantes de servidores físicos
A92: cisco_apic_adapter | B92: 10.191.155.10 10.191.155.13 | C92: 70:79:90:A1:9E:6E | D92: (Huawei Technologies Co.,Ltd) | E92: Fabricantes de servidores físicos
A93: cisco_apic_adapter | B93: 10.119.104.8 | C93: 74:4A:A4:0B:18:FC | D93: (zte corporation) | E93: Fabricantes de servidores físicos
A94: cisco_apic_adapter | B94: 10.59.19.40 | C94: CC:BB:FE:13:E0:21 | D94: (Huawei Technologies Co.,Ltd) | E94: Fabricantes de servidores físicos
A95: cisco_apic_adapter | B95: 10.152.54.151 | C95: 44:E9:68:66:BB:B6 | D95: (Huawei Technologies Co.,Ltd) | E95: Fabricantes de servidores físicos
A96: cisco_apic_adapter cisco_apic_adapter cisco_apic_adapter cisco_apic_adapter cisco_apic_adapter | B96: 10.59.162.174 | C96: 80:30:E0:05:AF:E0 | D96: (Hewlett Packard Enterprise) | E96: Fabricantes de servidores físicos
A97: cisco_apic_adapter | B97: 10.119.109.66 | C97: 0C:41:E9:7B:42:19 | D97: (Huawei Technologies Co.,Ltd) | E97: Fabricantes de servidores físicos
A98: cisco_apic_adapter | B98: 10.59.198.206 | C98: 08:F1:EA:80:D7:A2 | D98: (Hewlett Packard Enterprise) | E98: Fabricantes de servidores físicos
A99: cisco_apic_adapter cisco_apic_adapter cisco_apic_adapter cisco_apic_adapter cisco_apic_adapter | B99: 10.59.152.217 | C99: D0:67:26:C8:E3:20 | D99: (Hewlett Packard Enterprise) | E99: Fabricantes de servidores físicos
A100: cisco_apic_adapter cisco_apic_adapter cisco_apic_adapter cisco_apic_adapter cisco_apic_adapter | B100: 10.59.127.88 | C100: 80:30:E0:05:98:A0 | D100: (Hewlett Packard Enterprise) | E100: Fabricantes de servidores físicos
A101: cisco_apic_adapter | C101: 20:67:7C:19:D9:B9 | D101: (Hewlett Packard Enterprise) | E101: Fabricantes de servidores físicos
A102: cisco_apic_adapter cisco_apic_adapter cisco_apic_adapter cisco_apic_adapter cisco_apic_adapter | B102: 10.59.82.220 | C102: 80:30:E0:05:EB:00 | D102: (Hewlett Packard Enterprise) | E102: Fabricantes de servidores físicos
A103: cisco_apic_adapter | B103: 10.59.85.4 | C103: 48:DF:37:81:72:58 | D103: (Hewlett Packard Enterprise) | E103: Fabricantes de servidores físicos
A104: cisco_apic_adapter cisco_apic_adapter | B104: 10.119.251.101 | C104: 48:43:5A:C4:B2:59 | D104: (Huawei Technologies Co.,Ltd) | E104: Fabricantes de servidores físicos
A105: cisco_apic_adapter cisco_apic_adapter | B105: 10.119.200.188 | C105: 74:9D:8F:8D:36:57 | D105: (Huawei Technologies Co.,Ltd) | E105: Fabricantes de servidores físicos
A106: cisco_apic_adapter cisco_apic_adapter | B106: 10.119.200.189 | C106: 48:43:5A:59:65:A7 | D106: (Huawei Technologies Co.,Ltd) | E106: Fabricantes de servidores físicos
A107: cisco_apic_adapter | B107: 10.119.104.7 | C107: 74:4A:A4:0B:1B:E0 | D107: (zte corporation) | E107: Fabricantes de servidores físicos
A108: cisco_apic_adapter | C108: 00:50:56:81:27:74 | D108: (VMware, Inc.) | E108: Fabricantes/Administradores de servidores virtuales y soluciones de virtualización
A109: cisco_apic_adapter cisco_apic_adapter cisco_apic_adapter cisco_apic_adapter cisco_apic_adapter | B109: 10.59.154.228 | C109: 80:30:E0:05:94:10 | D109: (Hewlett Packard Enterprise) | E109: Fabricantes de servidores físicos
...

Sheet Inventario Identificados
A3: Identificados (No servidores) - Inventario
A4: Adaptadores | B4: IPs | C4: MACs | D4: Manufacturer | E4: Clasificacion
A5: cisco_adapter cisco_apic_adapter cisco_apic_adapter csv_adapter csv_adapter | B5: 10.119.238.60 | C5: 00:00:0C:07:AC:02 | D5: (Cisco Systems, Inc) | E5: Fabricantes de servidores físicos
A6: cisco_adapter cisco_apic_adapter cisco_apic_adapter csv_adapter csv_adapter | B6: 10.119.236.116 | C6: 00:00:0C:07:AC:03 | D6: (Cisco Systems, Inc) | E6: Fabricantes de servidores físicos
A7: cisco_adapter cisco_apic_adapter | B7: 10.191.83.14 | C7: 00:17:A4:77:00:CE | D7: (Hewlett Packard) | E7: HP (impresoras o PCs)
A8: cisco_adapter cisco_adapter cisco_apic_adapter cisco_apic_adapter cisco_apic_adapter | B8: 10.119.242.200 | C8: 00:00:0C:07:AC:01 | D8: (Cisco Systems, Inc) | E8: Fabricantes de servidores físicos
A9: cisco_adapter cisco_apic_adapter cisco_apic_adapter | B9: 10.119.238.124 | C9: 00:00:0C:07:AC:E4 | D9: (Cisco Systems, Inc) | E9: Fabricantes de servidores físicos
A10: cisco_adapter cisco_apic_adapter cisco_apic_adapter cisco_apic_adapter | B10: 10.119.236.84 | C10: 00:00:0C:07:AC:0B | D10: (Cisco Systems, Inc) | E10: Fabricantes de servidores físicos
A11: cisco_apic_adapter nagios_xi_adapter | B11: 10.191.184.132 | C11: 00:17:A4:77:44:00 | D11: (Hewlett Packard) | E11: HP (impresoras o PCs)
A12: cisco_apic_adapter nagios_xi_adapter | B12: 10.191.184.133 | C12: 00:17:A4:77:44:06 | D12: (Hewlett Packard) | E12: HP (impresoras o PCs)
A13: cisco_apic_adapter nagios_xi_adapter | B13: 10.191.184.137 | C13: 00:17:A4:77:44:18 | D13: (Hewlett Packard) | E13: HP (impresoras o PCs)
A14: cisco_apic_adapter nagios_xi_adapter | B14: 10.191.184.139 | C14: 00:17:A4:77:44:0C | D14: (Hewlett Packard) | E14: HP (impresoras o PCs)
A15: cisco_apic_adapter nagios_xi_adapter | B15: 10.191.184.143 | C15: 00:17:A4:77:44:10 | D15: (Hewlett Packard) | E15: HP (impresoras o PCs)
... A25: cisco_apic_adapter nagios_xi_adapter | B25: 10.119.133.7 | C25: 00:17:A4:77:E8:2A | D25: (Hewlett Packard) | E25: HP (impresoras o PCs)
A26: cisco_apic_adapter | C26: 44:1E:A1:76:03:7E | D26: (Hewlett Packard) | E26: HP (impresoras o PCs)
A27: cisco_apic_adapter | C27: 6C:3B:E5:AA:AE:B1 | D27: (Hewlett Packard) | E27: HP (impresoras o PCs)
A28: cisco_apic_adapter | C28: D8:9D:67:2A:CD:84 | D28: (Hewlett Packard) | E28: HP (impresoras o PCs)
A29: cisco_apic_adapter | C29: 6C:3B:E5:AB:32:81 | D29: (Hewlett Packard) | E29: HP (impresoras o PCs)
A30: cisco_apic_adapter | B30: 10.119.3.78 | C30: 00:E0:27:12:D9:A8 | D30: (Dux, Inc.) | E30: Energización
A31: cisco_apic_adapter | B31: 10.59.129.73 | C31: 30:E1:71:64:FA:45 | D31: (Hewlett Packard) | E31: HP (impresoras o PCs)
A32: cisco_apic_adapter | B32: 10.119.149.159 | C32: 00:17:A4:77:94:64 | D32: (Hewlett Packard) | E32: HP (impresoras o PCs)
A33: cisco_apic_adapter | B33: 10.119.172.10 | C33: FC:15:B4:1A:E0:D9 | D33: (Hewlett Packard) | E33: HP (impresoras o PCs)
A34: cisco_apic_adapter | C34: E8:39:35:01:05:A2 | D34: (Hewlett Packard) | E34: HP (impresoras o PCs)
A35: cisco_apic_adapter | B35: 10.59.89.7 | C35: 30:E1:71:64:6A:A1 | D35: (Hewlett Packard) | E35: HP (impresoras o PCs)
A36: cisco_apic_adapter | B36: 10.119.157.32 | C36: 00:60:16:77:F3:14 | D36: (Clariion) | E36: Almacenamiento
A37: cisco_apic_adapter | B37: 10.119.186.30 10.119.186.32 | C37: 80:C1:6E:68:99:9D | D37: (Hewlett Packard) | E37: HP (impresoras o PCs)
A38: cisco_apic_adapter | B38: 10.119.186.31 | C38: 80:C1:6E:68:99:99 | D38: (Hewlett Packard) | E38: HP (impresoras o PCs)
A39: cisco_apic_adapter | B39: 10.119.186.58 10.119.186.60 | C39: F0:92:1C:0C:73:7E | D39: (Hewlett Packard) | E39: HP (impresoras o PCs)
A40: cisco_apic_adapter | B40: 10.119.186.18 10.119.186.20 | C40: 2C:59:E5:34:7A:AC | D40: (Hewlett Packard) | E40: HP (impresoras o PCs)
A41: cisco_apic_adapter | B41: 10.119.186.22 | C41: F0:92:1C:04:09:09 | D41: (Hewlett Packard) | E41: HP (impresoras o PCs)
A42: cisco_apic_adapter | B42: 10.119.153.70 10.119.153.71 | C42: 14:58:D0:57:BD:08 | D42: (Hewlett Packard) | E42: HP (impresoras o PCs)
A43: cisco_apic_adapter | B43: 10.119.157.64 | C43: 00:07:6E:02:5D:DD | D43: (Sinetica Corporation Limited) | E43: Varios
A44: cisco_apic_adapter | B44: 10.119.149.54 | C44: F0:92:1C:11:B9:6D | D44: (Hewlett Packard) | E44: HP (impresoras o PCs)
A45: cisco_apic_adapter | B45: 10.119.149.70 | C45: F0:92:1C:09:79:CA | D45: (Hewlett Packard) | E45: HP (impresoras o PCs)
A46: cisco_apic_adapter | C46: F0:92:1C:08:B9:B1 | D46: (Hewlett Packard) | E46: HP (impresoras o PCs)
A47: cisco_apic_adapter | B47: 10.191.136.43 | C47: 98:4B:E1:6C:D7:6C | D47: (Hewlett Packard) | E47: HP (impresoras o PCs)
A48: cisco_apic_adapter | B48: 10.119.182.15 | C48: 30:E1:71:56:27:48 | D48: (Hewlett Packard) | E48: HP (impresoras o PCs)
A49: cisco_apic_adapter | B49: 10.191.83.38 | C49: 00:17:A4:77:01:A0 | D49: (Hewlett Packard) | E49: HP (impresoras o PCs)
A50: cisco_apic_adapter | B50: 10.191.105.72 10.191.105.78 | C50: 3C:D9:2B:F5:FB:DE | D50: (Hewlett Packard) | E50: HP (impresoras o PCs)
A51: cisco_apic_adapter | B51: 10.191.163.10 10.191.163.19 | C51: 00:17:A4:77:40:28 | D51: (Hewlett Packard) | E51: HP (impresoras o PCs)
...

Sheet No Identificados
B2: Row Labels | C2: Count of Clasificacion
B3: Windows 10 | C3: 1
B4: (blank)
B5: Grand Total | C5: 1

Sheet Identificados (OTROS)
B2: Row Labels | C2: Count of Clasificacion
B3: Windows 10 | C3: 1
B4: (blank)
B5: Grand Total | C5: 1

Sheet Adaptadores integrados
B2: Adaptador | C2: Región | D2: Sitio | E2: Responsable | F2: Estatus | G2: Descripción
B3: Cisco APIC | C3: R9 | D3: IXTLAHUACA | E3: Carlos Villafranca Bonilla | F3: Exitoso | G3: El Cisco Application Policy Infrastructure Controller (APIC) es el componente arquitectónico principal de Cisco ACI. Es el punto unificado para la automatización y gestión de la infraestructura de Cisco ACI, la aplicación de políticas y el monitoreo de salud, optimizando el rendimiento y la agilidad.
B4: Cortex | D4: https://api-scitumcert.xdr.us.paloaltonetworks.com | E4: Jorge Alvarado | F4: Exitoso | G4: Palo Alto Networks Cortex XDR es una aplicación de detección y respuesta que integra de forma nativa datos de red, endpoint y nube para detectar amenazas y detener ataques sofisticados.
B5: Vmware | D5: 10.119.78.210 | E5: Roman García Bernal | F5: Exitoso | G5: VMware ESXi es un hipervisor de clase empresarial, tipo 1, diseñado para implementar y gestionar computadoras virtuales. VMware vSphere es la plataforma de virtualización para computación en la nube de VMware.
D6: 10.191.141.20
D7: 10.59.205.39
D8: 10.59.205.40
B9: Vmware | D9: https://vcpvmvcsa01.telcelcloud.dt | E9: Francisco Javier Reyes Alcántara | F9: Exitoso | G9: VMware ESXi es un hipervisor de clase empresarial, tipo 1, diseñado para implementar y gestionar computadoras virtuales. VMware vSphere es la plataforma de virtualización para computación en la nube de VMware.
B10: Microsoft AD | D10: telcel.net | E10: Rocio Castro | F10: Exitoso | G10: Microsoft Active Directory (AD) es un servicio de directorio para redes de dominio en Windows que autentica y autoriza a todos los usuarios y computadoras.
D11: corpamx.com
B12: Tenable Nessus | D12: 10.152.30.219 | E12: José Juan León | F12: Exitoso | G12: Tenable Nessus es una plataforma de análisis de vulnerabilidades para auditores y analistas de seguridad.
B13: Tenable.sc (SecurityCenter) | D13: 10.152.30.218 | E13: José Juan León | F13: Exitoso | G13: Tenable.sc (anteriormente SecurityCenter) consolida y evalúa datos de vulnerabilidades, priorizando los riesgos de seguridad.
B14: HPE OneView | D14: https://10.59.198.91/#/login | E14: Ernesto David Vergara | F14: Exitoso | G14: HPE OneView es una solución integrada de gestión de TI que transforma el cómputo, el almacenamiento y la red en una infraestructura definida por software para automatizar tareas.
B15: Red Hat Satellite | D15: https://10.119.111.123/users/login | E15: Jorge Jimenez Matus | F15: Exitoso | G15: Red Hat Satellite es una solución de gestión de sistemas utilizada para implementar, configurar y mantener sistemas en entornos físicos, virtuales y en la nube.
B16: Dynatrace | D16: Dynatrace - MoSER (OYM) | E16: Ernesto David Vergara | F16: Exitoso | G16: Dynatrace es una plataforma de inteligencia de software que ofrece gestión del rendimiento de aplicaciones y monitoreo de infraestructura en la nube.
B17: Nagios | D17: https://10.59.230.86/nagiosxi/api/v1/ | E17: Ernesto David Vergara | F17: Exitoso | G17: Nagios XI ofrece monitoreo empresarial de servidores y redes.
B18: Huawei eSight | D18: https://10.34.226.212:31943/ | E18: Ernesto David Vergara | F18: En revisión por parte de axonius | G18: Huawei eSight es una plataforma empresarial de operación y mantenimiento (O&M) que ofrece gestión convergente entre múltiples proveedores y productos, monitoreo visualizado y análisis inteligente para dispositivos de TIC empresariales.
B19: vRops (Vmware Aria Operations) | D19: https://vcppvmvrop01.telcelcloud.dt | E19: Alvaro Garcia | F19: Exitoso | G19: VMware vRealize Operations (vROps) ofrece una plataforma de gestión de operaciones de TI para entornos privados, híbridos y multinube, abarcando infraestructura física, virtual y en la nube, incluidos máquinas virtuales (VMs) y contenedores.
B20: IES – Assurance -- Huawei | E20: Horacio Hernandez Bautista | F20: Sin adaptador | G20: iES Assurance de Huawei es una solución diseñada para la gestión y aseguramiento de la calidad de los servicios en redes y sistemas de telecomunicaciones.
B21: UIM - Unified Infrastructure Management à Broadcomm | E21: Horacio Hernandez Bautista | F21: Sin adaptador | G21: UIM proporciona una solución única y basada en análisis para una gestión eficaz y proactiva de infraestructuras de TI híbridas, modernas y en la nube.
B22: OBM - Operation Bridge Manager | E22: Horacio Hernandez Bautista | F22: Sin adaptador | G22: Operations Bridge Manager descubre y monitorea automáticamente la infraestructura de TI de una empresa mediante la recopilación de datos de topología y eventos.
B23: Centreon | E23: Alfonso Ruvalcaba/Alvaro García | F23: Sin adaptador | G23: Centreon es un software de monitorización de TI que ayuda a las empresas a garantizar la disponibilidad y el rendimiento de su TI.
B24: Gestor OBM | E24: Alfonso Ruvalcaba/Alvaro García | F24: Sin adaptador
B25: Grafana | E25: Alfonso Ruvalcaba/Alvaro García | F25: Sin adaptador | G25: Grafana es una solución de análisis y monitoreo de código abierto para todo tipo de bases de datos.
B26: Gestor Cisco Prime (CUOM) | E26: Alfonso Ruvalcaba/Alvaro García | F26: Existe el adaptador sin embargo el ing Alfonso Ruvalcaba solicita que cualquier información o acceso se solicite a través de subdirección | G26: Cisco Prime ofrece un conjunto de herramientas para automatizar la gestión de redes cableadas e inalámbricas de Cisco.
B27: CUCM (Call Manager de Cisco) | E27: Alfonso Ruvalcaba/Alvaro García | F27: Sin adaptador | G27: Cisco Unified Communications Manager lleva las características y capacidades de la telefonía para empresas a los dispositivos de red de telefonía por paquetes, tales como teléfonos IP, gateways de voz a través de IP (VoIP) y aplicaciones multimedia.
B28: Red Hat Virtualization | E28: Ricardo Herrera | F28: En proceso de desarrollo por axonius | G28: Red Hat Virtualization es una plataforma de virtualización de clase empresarial producida por Red Hat. Su objetivo es virtualizar aplicaciones importantes en el centro de datos empresarial mientras se logra el rendimiento, la resistencia y la seguridad.
B29: Trend Micro Deep Security | D29: https://10.152.30.88 | E29: Aldo Cruz | F29: Exitoso | G29: Trend Micro Deep Security puede parchear automáticamente vulnerabilidades en servidores, entornos de nube, VDI y aplicaciones de forma virtual.
B30: Vmware | C30: VDI | D30: https://10.119.251.71 | E30: Victor Rosas | F30: Exitoso | G30: VMware ESXi es un hipervisor de clase empresarial, tipo 1, diseñado para implementar y gestionar computadoras virtuales. VMware vSphere es la plataforma de virtualización para computación en la nube de VMware.
D31: https://10.54.137.234
D32: https://10.119.173.23/ui
B33: CSV Manual | D33: Tango | E33: Veronica de la Rosa | F33: Exitoso | G33: El adaptador CSV importa archivos .csv con información de inventario, incluyendo datos de dispositivos, usuarios y software instalado.
B34: CSV Manual | D34: Digital view | E34: Gerardo Arellano | F34: Exitoso | G34: El adaptador CSV importa archivos .csv con información de inventario, incluyendo datos de dispositivos, usuarios y software instalado.
B35: Digital view | E35: Gerardo Arellano | F35: En espera de información para iniciar el desarrollo del adaptador, la informción pendiente es por parte del proveedor huawei | G35: Digital View se enfoca en la visualización de datos de redes, servidores, almacenamiento y otros componentes de infraestructura, proporcionando herramientas para la supervisión, diagnóstico y análisis proactivo de posibles problemas.
