Workbook

Sheet Resumen
A2: Inventario ECATEPEC - Resumen
A3: Total Dispositivos y/o Direcciones IPs Descubiertos | F3: 693
B4: Dispositivos Identificados | F4: =F5+F10+F13+F14
C5: Total Servidores | F5: 15
D6: Servidores con Cortex | F6: 12
D7: Servidores sin Cortex | F7: 3
E8: Cortex Soportado | F8: =F7-F9
E9: Cortex no Soportado | F9: {=SUM(COUNTIFS(Inventario!E6:E1048576, {"Oracle Solaris","Windows Server 2008 R2","Windows Server 2003 R2","SunOS 10","SunOS 11.1","SunOS 11.2","SunOS 11.3","IBM AIX 6.1","IBM AIX 7.1","IBM AIX 7.2","IBM AIX 5.3","SunOS 9","SunOS 11.4.23.69.3","SunOS 11.0","SunOS 11.4","SunOS 11.4.0.15.0"}, Inventario!F6:F1048576, "NO"))}
C10: PCs | F10: 0
D11: PCs con Cortex | F11: 0
D12: PCs sin Cortex | F12: 0
C13: Dispositivos de Red o colaboración | F13: 560
C14: Otros dispositivos identificados (No servidores) | F14: =COUNTA('Inventario Identificados'!A5:A1048576)
B15: IPs No Identificados (Servidores) | F15: =COUNTA('Inventario No Identificados'!A5:A1048576)
B16: IPs No Identificados (No Vendor) | F16: =F3-F4-F15
A19: Servidores ECATEPEC - Vulnerabilidades
A20: Servidores con vulnerabilidades Críticas | E20: =COUNTIF('Inventario'!H6:H1048576,">0")
A21: Servidores con vulnerabilidades Altas | E21: =COUNTIF('Inventario'!I6:I1048576,">0")
A22: Servidores con EoL | E22: 15

Sheet Inventario - PC
A3: PCs ECATEPEC - Inventario
A4: No | B4: Hostname | C4: Dir IP | D4: MAC | E4: Sistema Operativo | F4: Cortex | G4: Virtual Patching

Sheet Inventario - Red
A3: Network Devices ECATEPEC - Inventario
A4: Adapter | B4: IPs | C4: MAC | D4: Manufacturer | E4: Hostname | F4: OS
A5: cisco_adapter cisco_apic_adapter cisco_apic_adapter cisco_apic_adapter csv_adapter csv_adapter csv_adapter | B5: 10.37.129.97 | C5: 00:00:0C:07:AC:45 | D5: (Cisco Systems, Inc)
A6: cisco_adapter cisco_apic_adapter cisco_apic_adapter cisco_apic_adapter cisco_apic_adapter cisco_apic_adapter csv_adapter csv_adapter csv_adapter | B6: 10.37.168.233 | C6: 00:00:0C:07:AC:1A | D6: (Cisco Systems, Inc)
A7: cisco_adapter cisco_apic_adapter cisco_apic_adapter cisco_apic_adapter cisco_apic_adapter cisco_apic_adapter cisco_apic_adapter cisco_apic_adapter csv_adapter csv_adapter csv_adapter | B7: 10.42.63.49 | C7: 00:00:0C:07:AC:18 | D7: (Cisco Systems, Inc)
A8: cisco_adapter cisco_apic_adapter cisco_apic_adapter cisco_apic_adapter cisco_apic_adapter cisco_apic_adapter csv_adapter csv_adapter csv_adapter | B8: 10.182.211.177 | C8: 00:00:0C:07:AC:44 | D8: (Cisco Systems, Inc)
A9: cisco_adapter cisco_apic_adapter cisco_apic_adapter cisco_apic_adapter cisco_apic_adapter cisco_apic_adapter csv_adapter | B9: 10.182.210.89 | C9: 00:00:0C:07:AC:29 | D9: (Cisco Systems, Inc)
A10: cisco_adapter cisco_apic_adapter cisco_apic_adapter cisco_apic_adapter cisco_apic_adapter cisco_apic_adapter cisco_apic_adapter csv_adapter csv_adapter csv_adapter | B10: 10.42.43.17 | C10: 00:00:0C:07:AC:33 | D10: (Cisco Systems, Inc)
A11: cisco_adapter cisco_apic_adapter cisco_apic_adapter cisco_apic_adapter cisco_apic_adapter cisco_apic_adapter cisco_apic_adapter cisco_apic_adapter cisco_apic_adapter csv_adapter csv_adapter csv_adapter | B11: 10.232.166.150 | C11: 00:00:0C:07:AC:21 | D11: (Cisco Systems, Inc)
A12: cisco_adapter cisco_apic_adapter cisco_apic_adapter csv_adapter csv_adapter | B12: 10.42.2.1 | C12: 00:00:0C:07:AC:66 | D12: (Cisco Systems, Inc)
A13: cisco_adapter cisco_apic_adapter cisco_apic_adapter cisco_apic_adapter cisco_apic_adapter cisco_apic_adapter cisco_apic_adapter cisco_apic_adapter csv_adapter csv_adapter csv_adapter | B13: 10.42.63.41 | C13: 00:00:0C:07:AC:17 | D13: (Cisco Systems, Inc)
A14: cisco_adapter cisco_apic_adapter cisco_apic_adapter cisco_apic_adapter cisco_apic_adapter cisco_apic_adapter cisco_apic_adapter csv_adapter csv_adapter | B14: 10.42.70.33 | C14: 00:00:0C:07:AC:5D | D14: (Cisco Systems, Inc)
A15: cisco_adapter cisco_apic_adapter cisco_apic_adapter csv_adapter csv_adapter | B15: 10.233.166.30 | C15: 00:00:0C:07:AC:34 | D15: (Cisco Systems, Inc)
A16: cisco_adapter cisco_apic_adapter cisco_apic_adapter cisco_apic_adapter csv_adapter csv_adapter | B16: 10.42.70.9 | C16: 00:00:0C:07:AC:60 | D16: (Cisco Systems, Inc)
... A21: cisco_adapter cisco_apic_adapter cisco_apic_adapter cisco_apic_adapter cisco_apic_adapter | B21: 10.182.210.81 | C21: 00:00:0C:07:AC:28 | D21: (Cisco Systems, Inc)
A22: cisco_adapter cisco_adapter cisco_adapter cisco_adapter cisco_adapter cisco_adapter cisco_adapter cisco_adapter cisco_adapter cisco_adapter cisco_adapter cisco_apic_adapter cisco_apic_adapter cisco_apic_adapter cisco_apic_adapter cisco_apic_adapter cisco_apic_adapter cisco_apic_adapter cisco_apic_adapter cisco_apic_adapter cisco_apic_adapter cisco_apic_adapter cisco_apic_adapter cisco_apic_adapter cisco_apic_adapter cisco_apic_adapter cisco_apic_adapter cisco_apic_adapter cisco_apic_adapter cisco_apic_adapter cisco_apic_adapter cisco_apic_adapter cisco_apic_adapter cisco_apic_adapter cisco_apic_adapter cisco_apic_adapter cisco_apic_adapter cisco_apic_adapter cisco_apic_adapter cisco_apic_adapter cisco_apic_adapter cisco_apic_adapter cisco_apic_adapter cisco_apic_adapter cisco_apic_adapter cisco_apic_adapter cisco_apic_adapter cisco_apic_adapter cisco_apic_adapter cisco_apic_adapter cisco_apic_adapter cisco_apic_adapter cisco_apic_adapter cisco_apic_adapter cisco_apic_adapter cisco_apic_adapter cisco_apic_adapter cisco_apic_adapter cisco_apic_adapter cisco_apic_adapter cisco_apic_adapter cisco_apic_adapter cisco_apic_adapter cisco_apic_adapter cisco_apic_adapter cisco_apic_adapter | B22: 10.214.7.241 | C22: E8:ED:F3:3F:4D:91 | D22: (Cisco Systems, Inc) | E22: 9R_MAC_ASECATE_1.SSHDATIP | F22: Cisco IOS-XR
A23: cisco_adapter cisco_apic_adapter cisco_apic_adapter cisco_apic_adapter cisco_apic_adapter cisco_apic_adapter cisco_apic_adapter cisco_apic_adapter cisco_apic_adapter | B23: 10.146.133.68 10.146.152.212 10.146.160.212 10.146.172.68 10.146.220.84 10.182.125.44 10.182.29.253 10.225.12.92 | C23: 3C:19:7D:CC:71:70 | D23: (Ericsson AB)
A24: cisco_adapter cisco_apic_adapter | B24: 10.214.73.75 | C24: B8:11:4B:AE:52:E4 | D24: (Cisco Systems, Inc)
A25: cisco_adapter cisco_apic_adapter | B25: 10.214.73.74 | C25: B8:11:4B:AE:BF:F4 | D25: (Cisco Systems, Inc)
A26: cisco_adapter cisco_adapter cisco_adapter cisco_adapter cisco_adapter cisco_adapter cisco_adapter cisco_adapter cisco_adapter cisco_adapter cisco_adapter cisco_adapter cisco_apic_adapter cisco_apic_adapter cisco_apic_adapter cisco_apic_adapter cisco_apic_adapter cisco_apic_adapter cisco_apic_adapter cisco_apic_adapter cisco_apic_adapter cisco_apic_adapter cisco_apic_adapter cisco_apic_adapter cisco_apic_adapter cisco_apic_adapter cisco_apic_adapter cisco_apic_adapter cisco_apic_adapter cisco_apic_adapter cisco_apic_adapter cisco_apic_adapter cisco_apic_adapter cisco_apic_adapter cisco_apic_adapter cisco_apic_adapter cisco_apic_adapter cisco_apic_adapter cisco_apic_adapter cisco_apic_adapter cisco_apic_adapter cisco_apic_adapter cisco_apic_adapter cisco_apic_adapter cisco_apic_adapter cisco_apic_adapter cisco_apic_adapter cisco_apic_adapter cisco_apic_adapter cisco_apic_adapter cisco_apic_adapter cisco_apic_adapter cisco_apic_adapter cisco_apic_adapter cisco_apic_adapter cisco_apic_adapter cisco_apic_adapter cisco_apic_adapter cisco_apic_adapter cisco_apic_adapter cisco_apic_adapter cisco_apic_adapter cisco_apic_adapter cisco_apic_adapter cisco_apic_adapter cisco_apic_adapter cisco_apic_adapter cisco_apic_adapter cisco_apic_adapter cisco_apic_adapter cisco_apic_adapter cisco_apic_adapter cisco_apic_adapter cisco_apic_adapter cisco_apic_adapter cisco_apic_adapter cisco_apic_adapter cisco_apic_adapter | B26: 10.214.7.237 | C26: E8:ED:F3:41:1C:71 | D26: (Cisco Systems, Inc) | E26: 9R_MAC_ASECATE_2.SSHDATIP | F26: Cisco IOS-XR
A27: cisco_adapter cisco_apic_adapter | B27: 10.220.132.222 | C27: 3C:19:7D:E9:34:D3 | D27: (Ericsson AB)
A28: cisco_adapter cisco_apic_adapter | B28: 10.214.0.62 | C28: 3C:19:7D:E9:35:A4 | D28: (Ericsson AB)
A29: cisco_adapter cisco_apic_adapter | B29: 10.214.73.73 | C29: B8:11:4B:AE:A9:4C | D29: (Cisco Systems, Inc)
A30: cisco_adapter cisco_apic_adapter | B30: 10.214.0.70 | C30: 3C:19:7D:E9:34:D2 | D30: (Ericsson AB)
A31: cisco_adapter cisco_apic_adapter | B31: 10.214.0.66 | C31: 3C:19:7D:E9:34:6F | D31: (Ericsson AB)
A32: cisco_adapter cisco_apic_adapter | B32: 10.214.1.2 | C32: 00:18:B9:48:39:D9 | D32: (Cisco Systems, Inc)
A33: cisco_adapter cisco_apic_adapter | B33: 10.214.3.24 | C33: 00:1E:F7:EC:E0:F0 | D33: (Cisco Systems, Inc)
A34: cisco_adapter cisco_apic_adapter | B34: 10.214.1.6 | C34: F4:CF:E2:31:2A:45 | D34: (Cisco Systems, Inc)
A35: cisco_adapter cisco_apic_adapter | B35: 10.214.6.25 | C35: 00:04:96:52:14:67 | D35: (Extreme Networks Headquarters)
A36: cisco_adapter cisco_apic_adapter | B36: 10.214.1.10 | C36: 54:7C:69:8A:02:C5 | D36: (Cisco Systems, Inc)
A37: cisco_adapter cisco_apic_adapter | B37: 10.214.34.164 | C37: A4:A1:C2:EA:71:F5 | D37: (Ericsson AB)
A38: cisco_adapter cisco_apic_adapter cisco_apic_adapter cisco_apic_adapter cisco_apic_adapter | B38: 10.214.59.246 10.52.0.62 10.52.10.182 10.52.10.190 | C38: 90:38:09:BD:2A:95 | D38: (Ericsson AB)
... A274: cisco_adapter cisco_apic_adapter cisco_apic_adapter cisco_apic_adapter cisco_apic_adapter cisco_apic_adapter cisco_apic_adapter cisco_apic_adapter cisco_apic_adapter | B274: 10.146.133.69 10.146.152.213 10.146.160.213 10.146.172.69 10.146.220.85 10.182.125.45 10.182.29.251 10.225.12.93 | C274: 98:C5:DB:A2:FB:EA | D274: (Ericsson AB)
A275: cisco_apic_adapter csv_adapter | B275: 10.214.36.193 10.214.73.65 172.31.176.1 fc00::1 | E275: 9ACIAPICECATEPE01
A276: cisco_apic_adapter csv_adapter | B276: 10.214.36.196 172.31.186.194 | E276: 9ACI_SP_ECATEPE_201
A277: cisco_apic_adapter csv_adapter | B277: 10.214.36.194 10.214.73.66 172.31.176.2 fc00::1 | E277: 9ACIAPICECATEPE02
A278: cisco_apic_adapter csv_adapter | B278: 10.214.36.199 172.31.186.195 | E278: 9ACI_LO_ECATEPE_102
A279: cisco_apic_adapter csv_adapter | B279: 10.214.36.201 172.31.186.197 | E279: 9ACI_LE_ECATEPE_152
A280: cisco_apic_adapter csv_adapter | B280: 10.214.36.198 172.31.186.192 | E280: 9ACI_LO_ECATEPE_101
A281: cisco_apic_adapter csv_adapter | B281: 10.214.36.200 172.31.186.196 | E281: 9ACI_LE_ECATEPE_151
...

Sheet Inventario
A3: Servidores ECATEPEC - Inventario
A4: No | B4: Hostname | C4: Dir IP | D4: MAC | E4: Sistema Operativo | F4: Cortex | G4: Virtual Patching (Trend Micro) | H4: Vulnerabilidades | J4: Comentarios
H5: #Criticas | I5: #Altas
A6: 1 | B6: ECAFHPNBURBKP01 | C6: 130.1.1.85 | D6: 5C:6F:69:DB:E7:D0 | E6: Linux Red Hat 8.10 | F6: NO | G6: NO | H6: 77 | I6: 542 | J6: =IF(F6="SI", "NA", IF(OR(E6="Oracle Solaris", E6="Windows Server 2008 R2", E6="Windows Server 2003 R2", E6="SunOS 10", E6="SunOS 11.1", E6="SunOS 11.2", E6="SunOS 11.3", E6="IBM AIX 6.1", E6="IBM AIX 7.1", E6="IBM AIX 7.2", E6="IBM AIX 5.3", E6="SunOS 9", E6="SunOS 11.4.23.69.3", E6="SunOS 11.0", E6="SunOS 11.4", E6="SunOS 11.4.0.15.0"), "Cortex not supported", "NA"))
A7: 2 | B7: ECASM1A | C7: 10.214.27.230 130.1.1.230 172.19.4.30 172.19.5.30 200.68.130.150 | D7: 48:DF:37:30:C8:2D 48:DF:37:30:C8:2F F0:92:1C:13:EB:E0 F0:92:1C:13:EB:E4 | E7: Linux Red Hat 6.4 | F7: SI | G7: NO | H7: 1325 | I7: 3882 | J7: =IF(F7="SI", "NA", IF(OR(E7="Oracle Solaris", E7="Windows Server 2008 R2", E7="Windows Server 2003 R2", E7="SunOS 10", E7="SunOS 11.1", E7="SunOS 11.2", E7="SunOS 11.3", E7="IBM AIX 6.1", E7="IBM AIX 7.1", E7="IBM AIX 7.2", E7="IBM AIX 5.3", E7="SunOS 9", E7="SunOS 11.4.23.69.3", E7="SunOS 11.0", E7="SunOS 11.4", E7="SunOS 11.4.0.15.0"), "Cortex not supported", "NA"))
A8: 3 | B8: ECASM1B | C8: 10.214.27.231 130.1.1.231 172.19.4.31 172.19.5.31 200.68.130.151 | D8: 38:EA:A7:91:08:99 38:EA:A7:91:08:9A F0:92:1C:13:1E:90 F0:92:1C:13:1E:94 | E8: Linux Red Hat 6.4 | F8: SI | G8: NO | H8: 1386 | I8: 3994 | J8: =IF(F8="SI", "NA", IF(OR(E8="Oracle Solaris", E8="Windows Server 2008 R2", E8="Windows Server 2003 R2", E8="SunOS 10", E8="SunOS 11.1", E8="SunOS 11.2", E8="SunOS 11.3", E8="IBM AIX 6.1", E8="IBM AIX 7.1", E8="IBM AIX 7.2", E8="IBM AIX 5.3", E8="SunOS 9", E8="SunOS 11.4.23.69.3", E8="SunOS 11.0", E8="SunOS 11.4", E8="SunOS 11.4.0.15.0"), "Cortex not supported", "NA"))
A9: 4 | B9: ECASM1DBF | C9: 10.214.27.229 10.214.27.235 10.214.27.237 130.1.1.229 172.19.2.21 172.19.4.21 172.19.5.21 172.19.6.21 172.19.7.21 200.68.130.150 | D9: 2C:44:FD:7C:3B:F4 2C:44:FD:7C:3B:F5 2C:44:FD:7C:3B:F7 74:46:A0:72:25:A0 74:46:A0:72:25:A1 8C:DC:D4:59:C0:50 8C:DC:D4:59:C0:54 | E9: Linux Red Hat 6.10 | F9: SI | G9: NO | H9: 966 | I9: 2576 | J9: =IF(F9="SI", "NA", IF(OR(E9="Oracle Solaris", E9="Windows Server 2008 R2", E9="Windows Server 2003 R2", E9="SunOS 10", E9="SunOS 11.1", E9="SunOS 11.2", E9="SunOS 11.3", E9="IBM AIX 6.1", E9="IBM AIX 7.1", E9="IBM AIX 7.2", E9="IBM AIX 5.3", E9="SunOS 9", E9="SunOS 11.4.23.69.3", E9="SunOS 11.0", E9="SunOS 11.4", E9="SunOS 11.4.0.15.0"), "Cortex not supported", "NA"))
A10: 5 | B10: ECASM1C | C10: 10.214.27.232 130.1.1.232 172.19.4.32 172.19.5.32 200.68.130.151 | D10: 38:EA:A7:31:D0:11 38:EA:A7:31:D0:12 F0:92:1C:13:CE:28 F0:92:1C:13:CE:2C | E10: Linux Red Hat 6.4 | F10: SI | G10: NO | H10: 1325 | I10: 3861 | J10: =IF(F10="SI", "NA", IF(OR(E10="Oracle Solaris", E10="Windows Server 2008 R2", E10="Windows Server 2003 R2", E10="SunOS 10", E10="SunOS 11.1", E10="SunOS 11.2", E10="SunOS 11.3", E10="IBM AIX 6.1", E10="IBM AIX 7.1", E10="IBM AIX 7.2", E10="IBM AIX 5.3", E10="SunOS 9", E10="SunOS 11.4.23.69.3", E10="SunOS 11.0", E10="SunOS 11.4", E10="SunOS 11.4.0.15.0"), "Cortex not supported", "NA"))
A11: 6 | B11: ECASM1D | C11: 10.214.27.233 130.1.1.233 172.19.4.33 172.19.5.33 200.68.130.151 | D11: 48:DF:37:30:C8:C1 48:DF:37:30:C8:C3 F0:92:1C:13:CE:30 F0:92:1C:13:CE:34 | E11: Linux Red Hat 6.4 | F11: SI | G11: NO | H11: 1321 | I11: 3857 | J11: =IF(F11="SI", "NA", IF(OR(E11="Oracle Solaris", E11="Windows Server 2008 R2", E11="Windows Server 2003 R2", E11="SunOS 10", E11="SunOS 11.1", E11="SunOS 11.2", E11="SunOS 11.3", E11="IBM AIX 6.1", E11="IBM AIX 7.1", E11="IBM AIX 7.2", E11="IBM AIX 5.3", E11="SunOS 9", E11="SunOS 11.4.23.69.3", E11="SunOS 11.0", E11="SunOS 11.4", E11="SunOS 11.4.0.15.0"), "Cortex not supported", "NA"))
A12: 7 | B12: ECASM1DBE | C12: 10.214.27.228 10.214.27.234 10.214.27.236 10.214.27.238 130.1.1.234 172.19.2.20 172.19.4.20 172.19.5.20 172.19.6.20 172.19.7.20 200.68.130.150 | D12: 2C:44:FD:7C:3B:F0 2C:44:FD:7C:3B:F1 2C:44:FD:7C:3B:F3 74:46:A0:72:25:A4 74:46:A0:72:25:A5 8C:DC:D4:59:C2:D8 8C:DC:D4:59:C2:DC | E12: Linux Red Hat 6.10 | F12: SI | G12: NO | H12: 967 | I12: 2560 | J12: =IF(F12="SI", "NA", IF(OR(E12="Oracle Solaris", E12="Windows Server 2008 R2", E12="Windows Server 2003 R2", E12="SunOS 10", E12="SunOS 11.1", E12="SunOS 11.2", E12="SunOS 11.3", E12="IBM AIX 6.1", E12="IBM AIX 7.1", E12="IBM AIX 7.2", E12="IBM AIX 5.3", E12="SunOS 9", E12="SunOS 11.4.23.69.3", E12="SunOS 11.0", E12="SunOS 11.4", E12="SunOS 11.4.0.15.0"), "Cortex not supported", "NA"))
A13: 8 | B13: ECATM1A | C13: 10.214.36.165 130.1.1.165 172.19.1.20 172.20.4.51 172.20.5.51 172.20.8.51 200.68.130.130 | D13: D0:43:1E:EB:5E:B1 D0:43:1E:EB:5E:B3 D0:43:1E:EB:5E:B7 D0:43:1E:EB:5E:B9 D0:43:1E:EB:5E:BB | E13: Linux Red Hat 7.9 | F13: SI | G13: NO | H13: 556 | I13: 1312 | J13: =IF(F13="SI", "NA", IF(OR(E13="Oracle Solaris", E13="Windows Server 2008 R2", E13="Windows Server 2003 R2", E13="SunOS 10", E13="SunOS 11.1", E13="SunOS 11.2", E13="SunOS 11.3", E13="IBM AIX 6.1", E13="IBM AIX 7.1", E13="IBM AIX 7.2", E13="IBM AIX 5.3", E13="SunOS 9", E13="SunOS 11.4.23.69.3", E13="SunOS 11.0", E13="SunOS 11.4", E13="SunOS 11.4.0.15.0"), "Cortex not supported", "NA"))
A14: 9 | B14: ECATM1B | C14: 10.214.36.166 130.1.1.166 172.19.1.21 172.20.4.52 172.20.5.52 172.20.8.52 200.68.130.132 | D14: D0:43:1E:EB:5E:BE D0:43:1E:EB:5E:C0 D0:43:1E:EB:5E:C4 D0:43:1E:EB:5E:C6 D0:43:1E:EB:5E:C8 | E14: Linux Red Hat 7.9 | F14: SI | G14: NO | H14: 556 | I14: 1311 | J14: =IF(F14="SI", "NA", IF(OR(E14="Oracle Solaris", E14="Windows Server 2008 R2", E14="Windows Server 2003 R2", E14="SunOS 10", E14="SunOS 11.1", E14="SunOS 11.2", E14="SunOS 11.3", E14="IBM AIX 6.1", E14="IBM AIX 7.1", E14="IBM AIX 7.2", E14="IBM AIX 5.3", E14="SunOS 9", E14="SunOS 11.4.23.69.3", E14="SunOS 11.0", E14="SunOS 11.4", E14="SunOS 11.4.0.15.0"), "Cortex not supported", "NA"))
A15: 10 | B15: ECATM1D | C15: 10.214.36.168 130.1.1.168 172.19.1.23 172.20.4.54 172.20.5.54 172.20.8.54 200.68.130.130 | D15: D0:43:1E:EB:5E:D8 D0:43:1E:EB:5E:DA D0:43:1E:EB:5E:DE D0:43:1E:EB:5E:E0 D0:43:1E:EB:5E:E2 | E15: Linux Red Hat 7.9 | F15: SI | G15: NO | H15: 566 | I15: 1376 | J15: =IF(F15="SI", "NA", IF(OR(E15="Oracle Solaris", E15="Windows Server 2008 R2", E15="Windows Server 2003 R2", E15="SunOS 10", E15="SunOS 11.1", E15="SunOS 11.2", E15="SunOS 11.3", E15="IBM AIX 6.1", E15="IBM AIX 7.1", E15="IBM AIX 7.2", E15="IBM AIX 5.3", E15="SunOS 9", E15="SunOS 11.4.23.69.3", E15="SunOS 11.0", E15="SunOS 11.4", E15="SunOS 11.4.0.15.0"), "Cortex not supported", "NA"))
A16: 11 | B16: ECATM1C | C16: 10.214.36.167 130.1.1.167 172.19.1.22 172.20.4.53 172.20.5.53 172.20.8.53 200.68.130.132 | D16: D0:43:1E:EB:5E:CB D0:43:1E:EB:5E:CD D0:43:1E:EB:5E:D1 D0:43:1E:EB:5E:D3 D0:43:1E:EB:5E:D5 | E16: Linux Red Hat 7.9 | F16: SI | G16: NO | H16: 555 | I16: 1310 | J16: =IF(F16="SI", "NA", IF(OR(E16="Oracle Solaris", E16="Windows Server 2008 R2", E16="Windows Server 2003 R2", E16="SunOS 10", E16="SunOS 11.1", E16="SunOS 11.2", E16="SunOS 11.3", E16="IBM AIX 6.1", E16="IBM AIX 7.1", E16="IBM AIX 7.2", E16="IBM AIX 5.3", E16="SunOS 9", E16="SunOS 11.4.23.69.3", E16="SunOS 11.0", E16="SunOS 11.4", E16="SunOS 11.4.0.15.0"), "Cortex not supported", "NA"))
A17: 12 | B17: ECATM1DBH | C17: 10.214.33.197 10.214.33.199 10.214.33.200 10.214.36.172 10.214.36.174 10.214.36.178 130.1.1.172 172.20.4.58 172.20.5.58 192.168.1.2 192.168.2.2 200.68.130.151 | D17: D0:43:1E:EB:5F:0C D0:43:1E:EB:5F:0E D0:43:1E:EB:5F:12 D0:43:1E:EB:5F:14 D0:43:1E:EB:5F:16 D0:43:1E:EB:5F:17 | E17: Linux Red Hat 7.9 | F17: SI | G17: NO | H17: 560 | I17: 1339 | J17: =IF(F17="SI", "NA", IF(OR(E17="Oracle Solaris", E17="Windows Server 2008 R2", E17="Windows Server 2003 R2", E17="SunOS 10", E17="SunOS 11.1", E17="SunOS 11.2", E17="SunOS 11.3", E17="IBM AIX 6.1", E17="IBM AIX 7.1", E17="IBM AIX 7.2", E17="IBM AIX 5.3", E17="SunOS 9", E17="SunOS 11.4.23.69.3", E17="SunOS 11.0", E17="SunOS 11.4", E17="SunOS 11.4.0.15.0"), "Cortex not supported", "NA"))
... A20: 15 | B20: ECATM1E | C20: 172.20.5.55 | D20: D0:43:1E:EB:5E:EB | E20: Linux Red Hat 7.9 | F20: NO | G20: NO | H20: 556 | I20: 1315 | J20: =IF(F20="SI", "NA", IF(OR(E20="Oracle Solaris", E20="Windows Server 2008 R2", E20="Windows Server 2003 R2", E20="SunOS 10", E20="SunOS 11.1", E20="SunOS 11.2", E20="SunOS 11.3", E20="IBM AIX 6.1", E20="IBM AIX 7.1", E20="IBM AIX 7.2", E20="IBM AIX 5.3", E20="SunOS 9", E20="SunOS 11.4.23.69.3", E20="SunOS 11.0", E20="SunOS 11.4", E20="SunOS 11.4.0.15.0"), "Cortex not supported", "NA"))

Sheet Inventario - EOL
A3: Servidores EOL ECATEPEC - Inventario
A4: No | B4: Hostname | C4: Dir IP | D4: MAC | E4: SISTEMA OPERATIVO | F4: Cortex | G4: Virtual Patching | H4: Software EoL
A6: 1 | B6: ECAFHPNBURBKP01 | C6: 130.1.1.85 | D6: 5C:6F:69:DB:E7:D0 | E6: Linux Red Hat 8.10 | F6: NO | G6: NO | H6: 4
A7: 2 | B7: ECASM1A | C7: 10.214.27.230 130.1.1.230 172.19.4.30 172.19.5.30 200.68.130.150 | D7: 48:DF:37:30:C8:2D 48:DF:37:30:C8:2F F0:92:1C:13:EB:E0 F0:92:1C:13:EB:E4 | E7: Linux Red Hat 6.4 | F7: SI | G7: NO | H7: 6
A8: 3 | B8: ECASM1B | C8: 10.214.27.231 130.1.1.231 172.19.4.31 172.19.5.31 200.68.130.151 | D8: 38:EA:A7:91:08:99 38:EA:A7:91:08:9A F0:92:1C:13:1E:90 F0:92:1C:13:1E:94 | E8: Linux Red Hat 6.4 | F8: SI | G8: NO | H8: 87
A9: 4 | B9: ECASM1DBF | C9: 10.214.27.229 10.214.27.235 10.214.27.237 130.1.1.229 172.19.2.21 172.19.4.21 172.19.5.21 172.19.6.21 172.19.7.21 200.68.130.150 | D9: 2C:44:FD:7C:3B:F4 2C:44:FD:7C:3B:F5 2C:44:FD:7C:3B:F7 74:46:A0:72:25:A0 74:46:A0:72:25:A1 8C:DC:D4:59:C0:50 8C:DC:D4:59:C0:54 | E9: Linux Red Hat 6.10 | F9: SI | G9: NO | H9: 17
A10: 5 | B10: ECASM1C | C10: 10.214.27.232 130.1.1.232 172.19.4.32 172.19.5.32 200.68.130.151 | D10: 38:EA:A7:31:D0:11 38:EA:A7:31:D0:12 F0:92:1C:13:CE:28 F0:92:1C:13:CE:2C | E10: Linux Red Hat 6.4 | F10: SI | G10: NO | H10: 85
A11: 6 | B11: ECASM1D | C11: 10.214.27.233 130.1.1.233 172.19.4.33 172.19.5.33 200.68.130.151 | D11: 48:DF:37:30:C8:C1 48:DF:37:30:C8:C3 F0:92:1C:13:CE:30 F0:92:1C:13:CE:34 | E11: Linux Red Hat 6.4 | F11: SI | G11: NO | H11: 89
A12: 7 | B12: ECASM1DBE | C12: 10.214.27.228 10.214.27.234 10.214.27.236 10.214.27.238 130.1.1.234 172.19.2.20 172.19.4.20 172.19.5.20 172.19.6.20 172.19.7.20 200.68.130.150 | D12: 2C:44:FD:7C:3B:F0 2C:44:FD:7C:3B:F1 2C:44:FD:7C:3B:F3 74:46:A0:72:25:A4 74:46:A0:72:25:A5 8C:DC:D4:59:C2:D8 8C:DC:D4:59:C2:DC | E12: Linux Red Hat 6.10 | F12: SI | G12: NO | H12: 17
A13: 8 | B13: ECATM1A | C13: 10.214.36.165 130.1.1.165 172.19.1.20 172.20.4.51 172.20.5.51 172.20.8.51 200.68.130.130 | D13: D0:43:1E:EB:5E:B1 D0:43:1E:EB:5E:B3 D0:43:1E:EB:5E:B7 D0:43:1E:EB:5E:B9 D0:43:1E:EB:5E:BB | E13: Linux Red Hat 7.9 | F13: SI | G13: NO | H13: 2
A14: 9 | B14: ECATM1B | C14: 10.214.36.166 130.1.1.166 172.19.1.21 172.20.4.52 172.20.5.52 172.20.8.52 200.68.130.132 | D14: D0:43:1E:EB:5E:BE D0:43:1E:EB:5E:C0 D0:43:1E:EB:5E:C4 D0:43:1E:EB:5E:C6 D0:43:1E:EB:5E:C8 | E14: Linux Red Hat 7.9 | F14: SI | G14: NO | H14: 2
A15: 10 | B15: ECATM1D | C15: 10.214.36.168 130.1.1.168 172.19.1.23 172.20.4.54 172.20.5.54 172.20.8.54 200.68.130.130 | D15: D0:43:1E:EB:5E:D8 D0:43:1E:EB:5E:DA D0:43:1E:EB:5E:DE D0:43:1E:EB:5E:E0 D0:43:1E:EB:5E:E2 | E15: Linux Red Hat 7.9 | F15: SI | G15: NO | H15: 3
A16: 11 | B16: ECATM1C | C16: 10.214.36.167 130.1.1.167 172.19.1.22 172.20.4.53 172.20.5.53 172.20.8.53 200.68.130.132 | D16: D0:43:1E:EB:5E:CB D0:43:1E:EB:5E:CD D0:43:1E:EB:5E:D1 D0:43:1E:EB:5E:D3 D0:43:1E:EB:5E:D5 | E16: Linux Red Hat 7.9 | F16: SI | G16: NO | H16: 2
A17: 12 | B17: ECATM1DBH | C17: 10.214.33.197 10.214.33.199 10.214.33.200 10.214.36.172 10.214.36.174 10.214.36.178 130.1.1.172 172.20.4.58 172.20.5.58 192.168.1.2 192.168.2.2 200.68.130.151 | D17: D0:43:1E:EB:5F:0C D0:43:1E:EB:5F:0E D0:43:1E:EB:5F:12 D0:43:1E:EB:5F:14 D0:43:1E:EB:5F:16 D0:43:1E:EB:5F:17 | E17: Linux Red Hat 7.9 | F17: SI | G17: NO | H17: 2
... A20: 15 | B20: ECATM1E | C20: 172.20.5.55 | D20: D0:43:1E:EB:5E:EB | E20: Linux Red Hat 7.9 | F20: NO | G20: NO | H20: 2

Sheet Inventario No Identificados
A3: No identificados (Servidores) - Inventario
A4: Adaptadores | B4: IPs | C4: MACs | D4: Manufacturer | E4: Clasificacion
A5: cisco_adapter cisco_apic_adapter | B5: 10.214.36.163 10.214.36.164 10.214.36.181 | C5: 0C:C4:7A:75:C5:28 | D5: (Super Micro Computer, Inc.) | E5: Fabricantes de servidores físicos
A6: cisco_adapter cisco_apic_adapter | B6: 10.214.58.53 | C6: 00:10:F3:74:4E:9E | D6: (Nexcom International Co., Ltd.) | E6: Fabricantes de servidores físicos
A7: cisco_adapter cisco_apic_adapter | B7: 10.214.58.52 10.214.58.54 10.214.58.55 | C7: 00:10:F3:74:4E:96 | D7: (Nexcom International Co., Ltd.) | E7: Fabricantes de servidores físicos
A8: cisco_adapter cisco_apic_adapter | B8: 10.214.6.23 | C8: 94:18:82:85:64:7C | D8: (Hewlett Packard Enterprise) | E8: Fabricantes de servidores físicos
A9: cisco_adapter cisco_apic_adapter | B9: 10.214.6.32 | C9: 94:18:82:85:54:68 | D9: (Hewlett Packard Enterprise) | E9: Fabricantes de servidores físicos
A10: cisco_adapter cisco_apic_adapter | B10: 10.214.57.142 | C10: A0:36:9F:2C:7E:11 | D10: (Intel Corporate) | E10: Fabricantes de hardware y componentes para servidores
A11: cisco_adapter cisco_apic_adapter | B11: 10.214.31.5 | C11: 00:10:E0:5F:A9:DC | D11: (Oracle Corporation) | E11: Fabricantes/Administradores de servidores virtuales y soluciones de virtualización
A12: cisco_adapter cisco_apic_adapter | B12: 10.214.36.173 | C12: D0:43:1E:EB:5F:21 | D12: (Dell Inc.) | E12: Fabricantes de servidores físicos
A13: cisco_adapter cisco_apic_adapter | B13: 10.214.31.6 | C13: 00:0C:29:B9:DA:70 | D13: (VMware, Inc.) | E13: Fabricantes/Administradores de servidores virtuales y soluciones de virtualización
A14: cisco_adapter cisco_apic_adapter | B14: 10.214.33.220 | C14: 1C:98:EC:2A:C6:80 | D14: (Hewlett Packard Enterprise) | E14: Fabricantes de servidores físicos
A15: cisco_adapter cisco_apic_adapter | B15: 10.214.73.84 | C15: 5C:ED:8C:2D:3C:AA | D15: (Hewlett Packard Enterprise) | E15: Fabricantes de servidores físicos
... A46: cisco_adapter cisco_apic_adapter | B46: 10.214.24.100 | C46: 44:A8:42:0E:A0:17 | D46: (Dell Inc.) | E46: Fabricantes de servidores físicos
A47: cisco_apic_adapter | C47: 0C:C4:7A:75:BD:18 | D47: (Super Micro Computer, Inc.) | E47: Fabricantes de servidores físicos
A48: cisco_apic_adapter | B48: 10.189.171.188 | C48: 74:4A:A4:2C:96:F0 | D48: (zte corporation) | E48: Fabricantes de servidores físicos
A49: cisco_apic_adapter | B49: 10.189.176.52 | C49: 74:4A:A4:2B:72:78 | D49: (zte corporation) | E49: Fabricantes de servidores físicos
A50: cisco_apic_adapter | B50: 10.189.176.30 10.189.222.30 | C50: 74:4A:A4:2B:73:20 | D50: (zte corporation) | E50: Fabricantes de servidores físicos
A51: cisco_apic_adapter | B51: 10.214.61.214 | C51: 74:4A:A4:2B:76:98 | D51: (zte corporation) | E51: Fabricantes de servidores físicos
A52: cisco_apic_adapter | B52: 10.214.61.204 | C52: C8:1F:BE:37:6A:AF | D52: (Huawei Technologies Co.,Ltd) | E52: Fabricantes de servidores físicos
A53: cisco_apic_adapter | B53: 10.214.61.250 | C53: 74:4A:A4:2B:6D:D0 | D53: (zte corporation) | E53: Fabricantes de servidores físicos
A54: cisco_apic_adapter | B54: 10.214.61.242 | C54: 74:4A:A4:2B:B6:D0 | D54: (zte corporation) | E54: Fabricantes de servidores físicos
A55: cisco_apic_adapter | B55: 10.214.61.252 | C55: 74:4A:A4:2D:22:E0 | D55: (zte corporation) | E55: Fabricantes de servidores físicos
A56: cisco_apic_adapter | B56: 10.198.145.22 | C56: 74:4A:A4:2D:22:A0 | D56: (zte corporation) | E56: Fabricantes de servidores físicos
A57: cisco_apic_adapter | B57: 10.189.176.64 10.189.222.64 | C57: 74:4A:A4:2B:7C:20 | D57: (zte corporation) | E57: Fabricantes de servidores físicos
A58: cisco_apic_adapter | B58: 10.206.37.42 | C58: FC:44:9F:94:8F:90 | D58: (zte corporation) | E58: Fabricantes de servidores físicos
A59: cisco_apic_adapter | C59: 00:10:E0:0D:67:6F | D59: (Oracle Corporation) | E59: Fabricantes/Administradores de servidores virtuales y soluciones de virtualización
A60: cisco_apic_adapter | B60: 10.214.61.234 | C60: 74:4A:A4:31:A8:F0 | D60: (zte corporation) | E60: Fabricantes de servidores físicos
A61: cisco_apic_adapter | B61: 10.189.176.26 | C61: 74:4A:A4:2D:2B:E8 | D61: (zte corporation) | E61: Fabricantes de servidores físicos
A62: cisco_apic_adapter | B62: 10.206.37.40 | C62: 74:4A:A4:31:A2:B8 | D62: (zte corporation) | E62: Fabricantes de servidores físicos
A63: cisco_adapter | B63: 10.214.6.159 | C63: 98:F5:37:F9:9E:C6 | D63: (zte corporation) | E63: Fabricantes de servidores físicos
A64: cisco_adapter | B64: 10.214.57.36 | C64: 00:10:E0:2E:A0:82 | D64: (Oracle Corporation) | E64: Fabricantes/Administradores de servidores virtuales y soluciones de virtualización
A65: cisco_adapter | B65: 10.214.57.43 | C65: 00:10:E0:5B:DD:8A | D65: (Oracle Corporation) | E65: Fabricantes/Administradores de servidores virtuales y soluciones de virtualización
A66: cisco_adapter | B66: 10.214.57.167 | C66: 00:10:E0:72:DE:5E | D66: (Oracle Corporation) | E66: Fabricantes/Administradores de servidores virtuales y soluciones de virtualización
A67: cisco_adapter | B67: 10.214.57.166 | C67: 00:21:28:DE:50:34 | D67: (Oracle Corporation) | E67: Fabricantes/Administradores de servidores virtuales y soluciones de virtualización
A68: cisco_adapter | B68: 10.214.57.169 | C68: 00:10:E0:3C:46:7A | D68: (Oracle Corporation) | E68: Fabricantes/Administradores de servidores virtuales y soluciones de virtualización
A69: cisco_adapter | B69: 10.214.57.170 | C69: 00:21:28:DE:4D:18 | D69: (Oracle Corporation) | E69: Fabricantes/Administradores de servidores virtuales y soluciones de virtualización
A70: cisco_adapter | B70: 10.214.3.75 | C70: 00:10:E0:B4:39:62 | D70: (Oracle Corporation) | E70: Fabricantes/Administradores de servidores virtuales y soluciones de virtualización
A71: cisco_adapter | B71: 10.214.73.68 | C71: 74:4A:A4:33:4A:18 | D71: (zte corporation) | E71: Fabricantes de servidores físicos
... A73: cisco_apic_adapter | B73: 10.214.61.72 | C73: 74:4A:A4:29:8B:D0 | D73: (zte corporation) | E73: Fabricantes de servidores físicos
...

Sheet Inventario Identificados
A3: Identificados (No servidores) - Inventario
A4: Adaptadores | B4: IPs | C4: MACs | D4: Manufacturer | E4: Clasificacion
A5: cisco_adapter cisco_apic_adapter | B5: 10.214.36.145 | C5: 00:A0:98:98:CC:0D | D5: (NetApp) | E5: Almacenamiento
A6: cisco_adapter cisco_apic_adapter | B6: 10.214.58.60 | C6: 24:A9:37:02:7F:F6 | D6: (PURE Storage) | E6: Almacenamiento
A7: cisco_adapter cisco_apic_adapter | B7: 10.214.36.143 | C7: 00:A0:98:98:CD:2A | D7: (NetApp) | E7: Almacenamiento
A8: cisco_adapter cisco_apic_adapter | B8: 10.214.36.133 | C8: 00:A0:98:98:CE:59 | D8: (NetApp) | E8: Almacenamiento
A9: cisco_adapter cisco_apic_adapter | B9: 10.214.6.45 | C9: 00:09:F5:04:B4:72 | D9: (Emerson Network Power Co.,Ltd) | E9: Energización
A10: cisco_adapter cisco_apic_adapter | B10: 10.214.36.144 | C10: 00:A0:98:98:CC:F7 | D10: (NetApp) | E10: Almacenamiento
A11: cisco_adapter cisco_apic_adapter | B11: 10.214.6.10 | C11: A4:5D:36:AB:30:80 | D11: (Hewlett Packard) | E11: HP (impresoras o PCs)
A12: cisco_adapter cisco_apic_adapter | B12: 10.214.36.132 | C12: 00:A0:98:98:CB:CE | D12: (NetApp) | E12: Almacenamiento
A13: cisco_adapter cisco_apic_adapter | B13: 10.214.6.42 | C13: B4:B5:2F:EB:DE:06 | D13: (Hewlett Packard) | E13: HP (impresoras o PCs)
A14: cisco_adapter cisco_apic_adapter | B14: 10.214.6.44 | C14: B4:B5:2F:EB:CE:3A | D14: (Hewlett Packard) | E14: HP (impresoras o PCs)
A15: cisco_adapter cisco_apic_adapter | B15: 10.214.6.16 | C15: 2C:44:FD:7D:A0:54 | D15: (Hewlett Packard) | E15: HP (impresoras o PCs)
... A37: cisco_adapter | B37: 10.146.176.92 | C37: 00:E0:86:18:84:AC | D37: (Emerson Network Power, Avocent Division) | E37: Energización

Sheet No Identificados
B2: Row Labels | C2: Count of Clasificacion
B3: Windows 10 | C3: 1
B4: (blank)
B5: Grand Total | C5: 1

Sheet Identificados (OTROS)
B2: Row Labels | C2: Count of Clasificacion
B3: Windows 10 | C3: 1
B4: (blank)
B5: Grand Total | C5: 1
